<robot name = "robot">
    <link name="Link0">
        <inertial>
            <origin xyz="0 0 0.7723965596229037" rpy="0 0 0"/>
            <mass value="1" />
            <inertia ixx="100" ixy="0" ixz="0" iyy="100" iyz="0" izz="100" />
        </inertial>
        <visual>
            <origin xyz="0 0 0.7723965596229037" rpy="0 0 0"/>
            <geometry>
                <box size="0.8382264304039913 0.22956336775728856 0.42978786886636383" />
            </geometry>
            <material name="blue">
                <color rgba="0 0.0 1.0 1.0"/>
            </material>
        </visual>
        <collision>
            <origin xyz="0 0 0.7723965596229037" rpy="0 0 0"/>
            <geometry>
                <box size="0.8382264304039913 0.22956336775728856 0.42978786886636383" />
            </geometry>
        </collision>
    </link>
    <joint name="Link0_Link1" type="revolute">
       <parent link="Link0"/>
       <child  link="Link1"/>
       <origin rpy="0 0 0" xyz="-0.4191132152019956 0.0 0.7723965596229037" />
       <axis xyz="0 1 0"/>
       <limit effort="0.0" lower="-3.14159" upper="3.14159" velocity="0.0"/>
    </joint>
    <link name="Link1">
        <inertial>
            <origin xyz="-0.10860600187514576 0.0 0.0" rpy="0 0 0"/>
            <mass value="1" />
            <inertia ixx="100" ixy="0" ixz="0" iyy="100" iyz="0" izz="100" />
        </inertial>
        <visual>
            <origin xyz="-0.10860600187514576 0.0 0.0" rpy="0 0 0"/>
            <geometry>
                <box size="0.2172120037502915 0.3919625581331935 0.21015667881063937" />
            </geometry>
            <material name="green">
                <color rgba="0 1.0 0.0 1.0"/>
            </material>
        </visual>
        <collision>
            <origin xyz="-0.10860600187514576 0.0 0.0" rpy="0 0 0"/>
            <geometry>
                <box size="0.2172120037502915 0.3919625581331935 0.21015667881063937" />
            </geometry>
        </collision>
    </link>
    <joint name="Link0_Link2" type="revolute">
       <parent link="Link0"/>
       <child  link="Link2"/>
       <origin rpy="0 0 0" xyz="0.4191132152019956 0.0 0.7723965596229037" />
       <axis xyz="0 1 0"/>
       <limit effort="0.0" lower="-3.14159" upper="3.14159" velocity="0.0"/>
    </joint>
    <link name="Link2">
        <inertial>
            <origin xyz="0.40193639013248017 0.0 0.0" rpy="0 0 0"/>
            <mass value="1" />
            <inertia ixx="100" ixy="0" ixz="0" iyy="100" iyz="0" izz="100" />
        </inertial>
        <visual>
            <origin xyz="0.40193639013248017 0.0 0.0" rpy="0 0 0"/>
            <geometry>
                <box size="0.8038727802649603 0.8202190628783586 0.5216508278267571" />
            </geometry>
            <material name="blue">
                <color rgba="0 0.0 1.0 1.0"/>
            </material>
        </visual>
        <collision>
            <origin xyz="0.40193639013248017 0.0 0.0" rpy="0 0 0"/>
            <geometry>
                <box size="0.8038727802649603 0.8202190628783586 0.5216508278267571" />
            </geometry>
        </collision>
    </link>
</robot>