<robot name = "robot">
    <link name="Link0">
        <inertial>
            <origin xyz="0 0 1.452548973947775" rpy="0 0 0"/>
            <mass value="1" />
            <inertia ixx="100" ixy="0" ixz="0" iyy="100" iyz="0" izz="100" />
        </inertial>
        <visual>
            <origin xyz="0 0 1.452548973947775" rpy="0 0 0"/>
            <geometry>
                <box size="0.597390324876379 0.6965656890680467 0.281349536233928" />
            </geometry>
            <material name="green">
                <color rgba="0 1.0 0.0 1.0"/>
            </material>
        </visual>
        <collision>
            <origin xyz="0 0 1.452548973947775" rpy="0 0 0"/>
            <geometry>
                <box size="0.597390324876379 0.6965656890680467 0.281349536233928" />
            </geometry>
        </collision>
    </link>
    <joint name="Link0_Link1" type="revolute">
       <parent link="Link0"/>
       <child  link="Link1"/>
       <origin rpy="0 0 0" xyz="0.2986951624381895 0.0 1.452548973947775" />
       <axis xyz="0 0 1"/>
       <limit effort="0.0" lower="-3.14159" upper="3.14159" velocity="0.0"/>
    </joint>
    <link name="Link1">
        <inertial>
            <origin xyz="0.20913311294443573 0.0 0.0" rpy="0 0 0"/>
            <mass value="1" />
            <inertia ixx="100" ixy="0" ixz="0" iyy="100" iyz="0" izz="100" />
        </inertial>
        <visual>
            <origin xyz="0.20913311294443573 0.0 0.0" rpy="0 0 0"/>
            <geometry>
                <box size="0.41826622588887147 0.20153727227085838 0.3710110475172157" />
            </geometry>
            <material name="blue">
                <color rgba="0 0.0 1.0 1.0"/>
            </material>
        </visual>
        <collision>
            <origin xyz="0.20913311294443573 0.0 0.0" rpy="0 0 0"/>
            <geometry>
                <box size="0.41826622588887147 0.20153727227085838 0.3710110475172157" />
            </geometry>
        </collision>
    </link>
    <joint name="Link0_Link2" type="revolute">
       <parent link="Link0"/>
       <child  link="Link2"/>
       <origin rpy="0 0 0" xyz="0.0 0.34828284453402336 1.452548973947775" />
       <axis xyz="0 1 0"/>
       <limit effort="0.0" lower="-3.14159" upper="3.14159" velocity="0.0"/>
    </joint>
    <link name="Link2">
        <inertial>
            <origin xyz="0.0 0.3239801548964424 0.0" rpy="0 0 0"/>
            <mass value="1" />
            <inertia ixx="100" ixy="0" ixz="0" iyy="100" iyz="0" izz="100" />
        </inertial>
        <visual>
            <origin xyz="0.0 0.3239801548964424 0.0" rpy="0 0 0"/>
            <geometry>
                <box size="0.4609029122623163 0.6479603097928848 0.6363896204634584" />
            </geometry>
            <material name="green">
                <color rgba="0 1.0 0.0 1.0"/>
            </material>
        </visual>
        <collision>
            <origin xyz="0.0 0.3239801548964424 0.0" rpy="0 0 0"/>
            <geometry>
                <box size="0.4609029122623163 0.6479603097928848 0.6363896204634584" />
            </geometry>
        </collision>
    </link>
    <joint name="Link2_Link3" type="revolute">
       <parent link="Link2"/>
       <child  link="Link3"/>
       <origin rpy="0 0 0" xyz="0.0 0.3239801548964424 -0.3181948102317292" />
       <axis xyz="0 1 0"/>
       <limit effort="0.0" lower="-3.14159" upper="3.14159" velocity="0.0"/>
    </joint>
    <link name="Link3">
        <inertial>
            <origin xyz="0.0 0.0 -0.30539293812960866" rpy="0 0 0"/>
            <mass value="1" />
            <inertia ixx="100" ixy="0" ixz="0" iyy="100" iyz="0" izz="100" />
        </inertial>
        <visual>
            <origin xyz="0.0 0.0 -0.30539293812960866" rpy="0 0 0"/>
            <geometry>
                <box size="0.5921876213355055 0.57075936757221 0.6107858762592173" />
            </geometry>
            <material name="green">
                <color rgba="0 1.0 0.0 1.0"/>
            </material>
        </visual>
        <collision>
            <origin xyz="0.0 0.0 -0.30539293812960866" rpy="0 0 0"/>
            <geometry>
                <box size="0.5921876213355055 0.57075936757221 0.6107858762592173" />
            </geometry>
        </collision>
    </link>
    <joint name="Link2_Link4" type="revolute">
       <parent link="Link2"/>
       <child  link="Link4"/>
       <origin rpy="0 0 0" xyz="0.0 0.3239801548964424 0.3181948102317292" />
       <axis xyz="1 0 0"/>
       <limit effort="0.0" lower="-3.14159" upper="3.14159" velocity="0.0"/>
    </joint>
    <link name="Link4">
        <inertial>
            <origin xyz="0.0 0.0 0.1601040216431965" rpy="0 0 0"/>
            <mass value="1" />
            <inertia ixx="100" ixy="0" ixz="0" iyy="100" iyz="0" izz="100" />
        </inertial>
        <visual>
            <origin xyz="0.0 0.0 0.1601040216431965" rpy="0 0 0"/>
            <geometry>
                <box size="0.31064127027419314 0.2735404275282039 0.320208043286393" />
            </geometry>
            <material name="blue">
                <color rgba="0 0.0 1.0 1.0"/>
            </material>
        </visual>
        <collision>
            <origin xyz="0.0 0.0 0.1601040216431965" rpy="0 0 0"/>
            <geometry>
                <box size="0.31064127027419314 0.2735404275282039 0.320208043286393" />
            </geometry>
        </collision>
    </link>
    <joint name="Link2_Link5" type="revolute">
       <parent link="Link2"/>
       <child  link="Link5"/>
       <origin rpy="0 0 0" xyz="0.0 0.6479603097928848 0.0" />
       <axis xyz="1 0 0"/>
       <limit effort="0.0" lower="-3.14159" upper="3.14159" velocity="0.0"/>
    </joint>
    <link name="Link5">
        <inertial>
            <origin xyz="0.0 0.22720673547533204 0.0" rpy="0 0 0"/>
            <mass value="1" />
            <inertia ixx="100" ixy="0" ixz="0" iyy="100" iyz="0" izz="100" />
        </inertial>
        <visual>
            <origin xyz="0.0 0.22720673547533204 0.0" rpy="0 0 0"/>
            <geometry>
                <box size="0.29513487125273574 0.4544134709506641 0.3817583537582113" />
            </geometry>
            <material name="green">
                <color rgba="0 1.0 0.0 1.0"/>
            </material>
        </visual>
        <collision>
            <origin xyz="0.0 0.22720673547533204 0.0" rpy="0 0 0"/>
            <geometry>
                <box size="0.29513487125273574 0.4544134709506641 0.3817583537582113" />
            </geometry>
        </collision>
    </link>
</robot>