<robot name = "robot">
    <link name="Link0">
        <inertial>
            <origin xyz="0 0 4.328593529393753" rpy="0 0 0"/>
            <mass value="1" />
            <inertia ixx="100" ixy="0" ixz="0" iyy="100" iyz="0" izz="100" />
        </inertial>
        <visual>
            <origin xyz="0 0 4.328593529393753" rpy="0 0 0"/>
            <geometry>
                <box size="0.20648000382991852 0.5260897381047772 0.8501105614732083" />
            </geometry>
            <material name="blue">
                <color rgba="0 0.0 1.0 1.0"/>
            </material>
        </visual>
        <collision>
            <origin xyz="0 0 4.328593529393753" rpy="0 0 0"/>
            <geometry>
                <box size="0.20648000382991852 0.5260897381047772 0.8501105614732083" />
            </geometry>
        </collision>
    </link>
    <joint name="Link0_Cube00" type="revolute">
       <parent link="Link0"/>
       <child  link="Cube00"/>
       <origin rpy="0 0 0" xyz="0.0 0.0 3.9035382486571493" />
       <axis xyz="0 1 0"/>
       <limit effort="0.0" lower="-3.14159" upper="3.14159" velocity="0.0"/>
    </joint>
    <link name="Cube00">
        <inertial>
            <origin xyz="0 0 0" rpy="0 0 0"/>
            <mass value="1" />
            <inertia ixx="100" ixy="0" ixz="0" iyy="100" iyz="0" izz="100" />
        </inertial>
        <visual>
            <origin xyz="0 0 0" rpy="0 0 0"/>
            <geometry>
                <box size="0 0 0" />
            </geometry>
            <material name="blue">
                <color rgba="0 0.0 1.0 1.0"/>
            </material>
        </visual>
        <collision>
            <origin xyz="0 0 0" rpy="0 0 0"/>
            <geometry>
                <box size="0 0 0" />
            </geometry>
        </collision>
    </link>
    <joint name="Cube00_Cube10" type="revolute">
       <parent link="Cube00"/>
       <child  link="Cube10"/>
       <origin rpy="0 0 0" xyz="0 0 0" />
       <axis xyz="1 0 0"/>
       <limit effort="0.0" lower="-3.14159" upper="3.14159" velocity="0.0"/>
    </joint>
    <link name="Cube10">
        <inertial>
            <origin xyz="0 0 0" rpy="0 0 0"/>
            <mass value="1" />
            <inertia ixx="100" ixy="0" ixz="0" iyy="100" iyz="0" izz="100" />
        </inertial>
        <visual>
            <origin xyz="0 0 0" rpy="0 0 0"/>
            <geometry>
                <box size="0 0 0" />
            </geometry>
            <material name="blue">
                <color rgba="0 0.0 1.0 1.0"/>
            </material>
        </visual>
        <collision>
            <origin xyz="0 0 0" rpy="0 0 0"/>
            <geometry>
                <box size="0 0 0" />
            </geometry>
        </collision>
    </link>
    <joint name="Cube10_Link1" type="revolute">
       <parent link="Cube10"/>
       <child  link="Link1"/>
       <origin rpy="0 0 0" xyz="0 0 0" />
       <axis xyz="0 0 1"/>
       <limit effort="0.0" lower="-3.14159" upper="3.14159" velocity="0.0"/>
    </joint>
    <link name="Link1">
        <inertial>
            <origin xyz="0.0 0.0 -0.27241538746042615" rpy="0 0 0"/>
            <mass value="1" />
            <inertia ixx="100" ixy="0" ixz="0" iyy="100" iyz="0" izz="100" />
        </inertial>
        <visual>
            <origin xyz="0.0 0.0 -0.27241538746042615" rpy="0 0 0"/>
            <geometry>
                <box size="0.6490955117892645 0.33562656241029387 0.5448307749208523" />
            </geometry>
            <material name="blue">
                <color rgba="0 0.0 1.0 1.0"/>
            </material>
        </visual>
        <collision>
            <origin xyz="0.0 0.0 -0.27241538746042615" rpy="0 0 0"/>
            <geometry>
                <box size="0.6490955117892645 0.33562656241029387 0.5448307749208523" />
            </geometry>
        </collision>
    </link>
    <joint name="Link1_Cube01" type="revolute">
       <parent link="Link1"/>
       <child  link="Cube01"/>
       <origin rpy="0 0 0" xyz="-0.32454775589463225 0.0 -0.27241538746042615" />
       <axis xyz="0 0 1"/>
       <limit effort="0.0" lower="-3.14159" upper="3.14159" velocity="0.0"/>
    </joint>
    <link name="Cube01">
        <inertial>
            <origin xyz="0 0 0" rpy="0 0 0"/>
            <mass value="1" />
            <inertia ixx="100" ixy="0" ixz="0" iyy="100" iyz="0" izz="100" />
        </inertial>
        <visual>
            <origin xyz="0 0 0" rpy="0 0 0"/>
            <geometry>
                <box size="0 0 0" />
            </geometry>
            <material name="blue">
                <color rgba="0 0.0 1.0 1.0"/>
            </material>
        </visual>
        <collision>
            <origin xyz="0 0 0" rpy="0 0 0"/>
            <geometry>
                <box size="0 0 0" />
            </geometry>
        </collision>
    </link>
    <joint name="Cube01_Link2" type="revolute">
       <parent link="Cube01"/>
       <child  link="Link2"/>
       <origin rpy="0 0 0" xyz="0 0 0" />
       <axis xyz="0 1 0"/>
       <limit effort="0.0" lower="-3.14159" upper="3.14159" velocity="0.0"/>
    </joint>
    <link name="Link2">
        <inertial>
            <origin xyz="-0.25396028801236126 0.0 0.0" rpy="0 0 0"/>
            <mass value="1" />
            <inertia ixx="100" ixy="0" ixz="0" iyy="100" iyz="0" izz="100" />
        </inertial>
        <visual>
            <origin xyz="-0.25396028801236126 0.0 0.0" rpy="0 0 0"/>
            <geometry>
                <box size="0.5079205760247225 0.35083914939602323 0.42292530024645497" />
            </geometry>
            <material name="blue">
                <color rgba="0 0.0 1.0 1.0"/>
            </material>
        </visual>
        <collision>
            <origin xyz="-0.25396028801236126 0.0 0.0" rpy="0 0 0"/>
            <geometry>
                <box size="0.5079205760247225 0.35083914939602323 0.42292530024645497" />
            </geometry>
        </collision>
    </link>
    <joint name="Link1_Cube02" type="revolute">
       <parent link="Link1"/>
       <child  link="Cube02"/>
       <origin rpy="0 0 0" xyz="0.32454775589463225 0.0 -0.27241538746042615" />
       <axis xyz="1 0 0"/>
       <limit effort="0.0" lower="-3.14159" upper="3.14159" velocity="0.0"/>
    </joint>
    <link name="Cube02">
        <inertial>
            <origin xyz="0 0 0" rpy="0 0 0"/>
            <mass value="1" />
            <inertia ixx="100" ixy="0" ixz="0" iyy="100" iyz="0" izz="100" />
        </inertial>
        <visual>
            <origin xyz="0 0 0" rpy="0 0 0"/>
            <geometry>
                <box size="0 0 0" />
            </geometry>
            <material name="blue">
                <color rgba="0 0.0 1.0 1.0"/>
            </material>
        </visual>
        <collision>
            <origin xyz="0 0 0" rpy="0 0 0"/>
            <geometry>
                <box size="0 0 0" />
            </geometry>
        </collision>
    </link>
    <joint name="Cube02_Cube12" type="revolute">
       <parent link="Cube02"/>
       <child  link="Cube12"/>
       <origin rpy="0 0 0" xyz="0 0 0" />
       <axis xyz="0 1 0"/>
       <limit effort="0.0" lower="-3.14159" upper="3.14159" velocity="0.0"/>
    </joint>
    <link name="Cube12">
        <inertial>
            <origin xyz="0 0 0" rpy="0 0 0"/>
            <mass value="1" />
            <inertia ixx="100" ixy="0" ixz="0" iyy="100" iyz="0" izz="100" />
        </inertial>
        <visual>
            <origin xyz="0 0 0" rpy="0 0 0"/>
            <geometry>
                <box size="0 0 0" />
            </geometry>
            <material name="blue">
                <color rgba="0 0.0 1.0 1.0"/>
            </material>
        </visual>
        <collision>
            <origin xyz="0 0 0" rpy="0 0 0"/>
            <geometry>
                <box size="0 0 0" />
            </geometry>
        </collision>
    </link>
    <joint name="Cube12_Link3" type="revolute">
       <parent link="Cube12"/>
       <child  link="Link3"/>
       <origin rpy="0 0 0" xyz="0 0 0" />
       <axis xyz="0 0 1"/>
       <limit effort="0.0" lower="-3.14159" upper="3.14159" velocity="0.0"/>
    </joint>
    <link name="Link3">
        <inertial>
            <origin xyz="0.27174599616349315 0.0 0.0" rpy="0 0 0"/>
            <mass value="1" />
            <inertia ixx="100" ixy="0" ixz="0" iyy="100" iyz="0" izz="100" />
        </inertial>
        <visual>
            <origin xyz="0.27174599616349315 0.0 0.0" rpy="0 0 0"/>
            <geometry>
                <box size="0.5434919923269863 0.21108518729154158 0.2779727702178152" />
            </geometry>
            <material name="blue">
                <color rgba="0 0.0 1.0 1.0"/>
            </material>
        </visual>
        <collision>
            <origin xyz="0.27174599616349315 0.0 0.0" rpy="0 0 0"/>
            <geometry>
                <box size="0.5434919923269863 0.21108518729154158 0.2779727702178152" />
            </geometry>
        </collision>
    </link>
    <joint name="Link2_Cube03" type="revolute">
       <parent link="Link2"/>
       <child  link="Cube03"/>
       <origin rpy="0 0 0" xyz="-0.5079205760247225 0.0 0.0" />
       <axis xyz="0 0 1"/>
       <limit effort="0.0" lower="-3.14159" upper="3.14159" velocity="0.0"/>
    </joint>
    <link name="Cube03">
        <inertial>
            <origin xyz="0 0 0" rpy="0 0 0"/>
            <mass value="1" />
            <inertia ixx="100" ixy="0" ixz="0" iyy="100" iyz="0" izz="100" />
        </inertial>
        <visual>
            <origin xyz="0 0 0" rpy="0 0 0"/>
            <geometry>
                <box size="0 0 0" />
            </geometry>
            <material name="blue">
                <color rgba="0 0.0 1.0 1.0"/>
            </material>
        </visual>
        <collision>
            <origin xyz="0 0 0" rpy="0 0 0"/>
            <geometry>
                <box size="0 0 0" />
            </geometry>
        </collision>
    </link>
    <joint name="Cube03_Cube13" type="revolute">
       <parent link="Cube03"/>
       <child  link="Cube13"/>
       <origin rpy="0 0 0" xyz="0 0 0" />
       <axis xyz="0 1 0"/>
       <limit effort="0.0" lower="-3.14159" upper="3.14159" velocity="0.0"/>
    </joint>
    <link name="Cube13">
        <inertial>
            <origin xyz="0 0 0" rpy="0 0 0"/>
            <mass value="1" />
            <inertia ixx="100" ixy="0" ixz="0" iyy="100" iyz="0" izz="100" />
        </inertial>
        <visual>
            <origin xyz="0 0 0" rpy="0 0 0"/>
            <geometry>
                <box size="0 0 0" />
            </geometry>
            <material name="blue">
                <color rgba="0 0.0 1.0 1.0"/>
            </material>
        </visual>
        <collision>
            <origin xyz="0 0 0" rpy="0 0 0"/>
            <geometry>
                <box size="0 0 0" />
            </geometry>
        </collision>
    </link>
    <joint name="Cube13_Link4" type="revolute">
       <parent link="Cube13"/>
       <child  link="Link4"/>
       <origin rpy="0 0 0" xyz="0 0 0" />
       <axis xyz="1 0 0"/>
       <limit effort="0.0" lower="-3.14159" upper="3.14159" velocity="0.0"/>
    </joint>
    <link name="Link4">
        <inertial>
            <origin xyz="-0.21820941225404647 0.0 0.0" rpy="0 0 0"/>
            <mass value="1" />
            <inertia ixx="100" ixy="0" ixz="0" iyy="100" iyz="0" izz="100" />
        </inertial>
        <visual>
            <origin xyz="-0.21820941225404647 0.0 0.0" rpy="0 0 0"/>
            <geometry>
                <box size="0.43641882450809294 0.34515981944204843 0.3858769885894946" />
            </geometry>
            <material name="blue">
                <color rgba="0 0.0 1.0 1.0"/>
            </material>
        </visual>
        <collision>
            <origin xyz="-0.21820941225404647 0.0 0.0" rpy="0 0 0"/>
            <geometry>
                <box size="0.43641882450809294 0.34515981944204843 0.3858769885894946" />
            </geometry>
        </collision>
    </link>
    <joint name="Link0_Link5" type="revolute">
       <parent link="Link0"/>
       <child  link="Link5"/>
       <origin rpy="0 0 0" xyz="0.0 -0.2630448690523886 4.328593529393753" />
       <axis xyz="0 1 0"/>
       <limit effort="0.0" lower="-3.14159" upper="3.14159" velocity="0.0"/>
    </joint>
    <link name="Link5">
        <inertial>
            <origin xyz="0.0 -0.19692552069661495 0.0" rpy="0 0 0"/>
            <mass value="1" />
            <inertia ixx="100" ixy="0" ixz="0" iyy="100" iyz="0" izz="100" />
        </inertial>
        <visual>
            <origin xyz="0.0 -0.19692552069661495 0.0" rpy="0 0 0"/>
            <geometry>
                <box size="0.22561443755033617 0.3938510413932299 0.3742036690846689" />
            </geometry>
            <material name="green">
                <color rgba="0 1.0 0.0 1.0"/>
            </material>
        </visual>
        <collision>
            <origin xyz="0.0 -0.19692552069661495 0.0" rpy="0 0 0"/>
            <geometry>
                <box size="0.22561443755033617 0.3938510413932299 0.3742036690846689" />
            </geometry>
        </collision>
    </link>
    <joint name="Link5_Cube05" type="revolute">
       <parent link="Link5"/>
       <child  link="Cube05"/>
       <origin rpy="0 0 0" xyz="0.0 -0.19692552069661495 0.18710183454233445" />
       <axis xyz="1 0 0"/>
       <limit effort="0.0" lower="-3.14159" upper="3.14159" velocity="0.0"/>
    </joint>
    <link name="Cube05">
        <inertial>
            <origin xyz="0 0 0" rpy="0 0 0"/>
            <mass value="1" />
            <inertia ixx="100" ixy="0" ixz="0" iyy="100" iyz="0" izz="100" />
        </inertial>
        <visual>
            <origin xyz="0 0 0" rpy="0 0 0"/>
            <geometry>
                <box size="0 0 0" />
            </geometry>
            <material name="blue">
                <color rgba="0 0.0 1.0 1.0"/>
            </material>
        </visual>
        <collision>
            <origin xyz="0 0 0" rpy="0 0 0"/>
            <geometry>
                <box size="0 0 0" />
            </geometry>
        </collision>
    </link>
    <joint name="Cube05_Cube15" type="revolute">
       <parent link="Cube05"/>
       <child  link="Cube15"/>
       <origin rpy="0 0 0" xyz="0 0 0" />
       <axis xyz="0 0 1"/>
       <limit effort="0.0" lower="-3.14159" upper="3.14159" velocity="0.0"/>
    </joint>
    <link name="Cube15">
        <inertial>
            <origin xyz="0 0 0" rpy="0 0 0"/>
            <mass value="1" />
            <inertia ixx="100" ixy="0" ixz="0" iyy="100" iyz="0" izz="100" />
        </inertial>
        <visual>
            <origin xyz="0 0 0" rpy="0 0 0"/>
            <geometry>
                <box size="0 0 0" />
            </geometry>
            <material name="blue">
                <color rgba="0 0.0 1.0 1.0"/>
            </material>
        </visual>
        <collision>
            <origin xyz="0 0 0" rpy="0 0 0"/>
            <geometry>
                <box size="0 0 0" />
            </geometry>
        </collision>
    </link>
    <joint name="Cube15_Link6" type="revolute">
       <parent link="Cube15"/>
       <child  link="Link6"/>
       <origin rpy="0 0 0" xyz="0 0 0" />
       <axis xyz="0 1 0"/>
       <limit effort="0.0" lower="-3.14159" upper="3.14159" velocity="0.0"/>
    </joint>
    <link name="Link6">
        <inertial>
            <origin xyz="0.0 0.0 0.17640499510418134" rpy="0 0 0"/>
            <mass value="1" />
            <inertia ixx="100" ixy="0" ixz="0" iyy="100" iyz="0" izz="100" />
        </inertial>
        <visual>
            <origin xyz="0.0 0.0 0.17640499510418134" rpy="0 0 0"/>
            <geometry>
                <box size="0.3237660395373147 0.31929002850457255 0.3528099902083627" />
            </geometry>
            <material name="green">
                <color rgba="0 1.0 0.0 1.0"/>
            </material>
        </visual>
        <collision>
            <origin xyz="0.0 0.0 0.17640499510418134" rpy="0 0 0"/>
            <geometry>
                <box size="0.3237660395373147 0.31929002850457255 0.3528099902083627" />
            </geometry>
        </collision>
    </link>
    <joint name="Link5_Link7" type="revolute">
       <parent link="Link5"/>
       <child  link="Link7"/>
       <origin rpy="0 0 0" xyz="0.0 -0.19692552069661495 -0.18710183454233445" />
       <axis xyz="0 0 1"/>
       <limit effort="0.0" lower="-3.14159" upper="3.14159" velocity="0.0"/>
    </joint>
    <link name="Link7">
        <inertial>
            <origin xyz="0.0 0.0 -0.186943654302973" rpy="0 0 0"/>
            <mass value="1" />
            <inertia ixx="100" ixy="0" ixz="0" iyy="100" iyz="0" izz="100" />
        </inertial>
        <visual>
            <origin xyz="0.0 0.0 -0.186943654302973" rpy="0 0 0"/>
            <geometry>
                <box size="0.3677728699615746 0.37217024394716297 0.373887308605946" />
            </geometry>
            <material name="green">
                <color rgba="0 1.0 0.0 1.0"/>
            </material>
        </visual>
        <collision>
            <origin xyz="0.0 0.0 -0.186943654302973" rpy="0 0 0"/>
            <geometry>
                <box size="0.3677728699615746 0.37217024394716297 0.373887308605946" />
            </geometry>
        </collision>
    </link>
    <joint name="Link5_Cube07" type="revolute">
       <parent link="Link5"/>
       <child  link="Cube07"/>
       <origin rpy="0 0 0" xyz="0.0 -0.3938510413932299 0.0" />
       <axis xyz="1 0 0"/>
       <limit effort="0.0" lower="-3.14159" upper="3.14159" velocity="0.0"/>
    </joint>
    <link name="Cube07">
        <inertial>
            <origin xyz="0 0 0" rpy="0 0 0"/>
            <mass value="1" />
            <inertia ixx="100" ixy="0" ixz="0" iyy="100" iyz="0" izz="100" />
        </inertial>
        <visual>
            <origin xyz="0 0 0" rpy="0 0 0"/>
            <geometry>
                <box size="0 0 0" />
            </geometry>
            <material name="blue">
                <color rgba="0 0.0 1.0 1.0"/>
            </material>
        </visual>
        <collision>
            <origin xyz="0 0 0" rpy="0 0 0"/>
            <geometry>
                <box size="0 0 0" />
            </geometry>
        </collision>
    </link>
    <joint name="Cube07_Link8" type="revolute">
       <parent link="Cube07"/>
       <child  link="Link8"/>
       <origin rpy="0 0 0" xyz="0 0 0" />
       <axis xyz="0 1 0"/>
       <limit effort="0.0" lower="-3.14159" upper="3.14159" velocity="0.0"/>
    </joint>
    <link name="Link8">
        <inertial>
            <origin xyz="0.0 -0.1663899755926162 0.0" rpy="0 0 0"/>
            <mass value="1" />
            <inertia ixx="100" ixy="0" ixz="0" iyy="100" iyz="0" izz="100" />
        </inertial>
        <visual>
            <origin xyz="0.0 -0.1663899755926162 0.0" rpy="0 0 0"/>
            <geometry>
                <box size="0.27354964725991676 0.3327799511852324 0.20646642920312105" />
            </geometry>
            <material name="blue">
                <color rgba="0 0.0 1.0 1.0"/>
            </material>
        </visual>
        <collision>
            <origin xyz="0.0 -0.1663899755926162 0.0" rpy="0 0 0"/>
            <geometry>
                <box size="0.27354964725991676 0.3327799511852324 0.20646642920312105" />
            </geometry>
        </collision>
    </link>
    <joint name="Link3_Cube08" type="revolute">
       <parent link="Link3"/>
       <child  link="Cube08"/>
       <origin rpy="0 0 0" xyz="0.5434919923269863 0.0 0.0" />
       <axis xyz="0 1 0"/>
       <limit effort="0.0" lower="-3.14159" upper="3.14159" velocity="0.0"/>
    </joint>
    <link name="Cube08">
        <inertial>
            <origin xyz="0 0 0" rpy="0 0 0"/>
            <mass value="1" />
            <inertia ixx="100" ixy="0" ixz="0" iyy="100" iyz="0" izz="100" />
        </inertial>
        <visual>
            <origin xyz="0 0 0" rpy="0 0 0"/>
            <geometry>
                <box size="0 0 0" />
            </geometry>
            <material name="blue">
                <color rgba="0 0.0 1.0 1.0"/>
            </material>
        </visual>
        <collision>
            <origin xyz="0 0 0" rpy="0 0 0"/>
            <geometry>
                <box size="0 0 0" />
            </geometry>
        </collision>
    </link>
    <joint name="Cube08_Cube18" type="revolute">
       <parent link="Cube08"/>
       <child  link="Cube18"/>
       <origin rpy="0 0 0" xyz="0 0 0" />
       <axis xyz="0 0 1"/>
       <limit effort="0.0" lower="-3.14159" upper="3.14159" velocity="0.0"/>
    </joint>
    <link name="Cube18">
        <inertial>
            <origin xyz="0 0 0" rpy="0 0 0"/>
            <mass value="1" />
            <inertia ixx="100" ixy="0" ixz="0" iyy="100" iyz="0" izz="100" />
        </inertial>
        <visual>
            <origin xyz="0 0 0" rpy="0 0 0"/>
            <geometry>
                <box size="0 0 0" />
            </geometry>
            <material name="blue">
                <color rgba="0 0.0 1.0 1.0"/>
            </material>
        </visual>
        <collision>
            <origin xyz="0 0 0" rpy="0 0 0"/>
            <geometry>
                <box size="0 0 0" />
            </geometry>
        </collision>
    </link>
    <joint name="Cube18_Link9" type="revolute">
       <parent link="Cube18"/>
       <child  link="Link9"/>
       <origin rpy="0 0 0" xyz="0 0 0" />
       <axis xyz="1 0 0"/>
       <limit effort="0.0" lower="-3.14159" upper="3.14159" velocity="0.0"/>
    </joint>
    <link name="Link9">
        <inertial>
            <origin xyz="0.13510612807427902 0.0 0.0" rpy="0 0 0"/>
            <mass value="1" />
            <inertia ixx="100" ixy="0" ixz="0" iyy="100" iyz="0" izz="100" />
        </inertial>
        <visual>
            <origin xyz="0.13510612807427902 0.0 0.0" rpy="0 0 0"/>
            <geometry>
                <box size="0.27021225614855804 0.343624230414598 0.20341581109683535" />
            </geometry>
            <material name="blue">
                <color rgba="0 0.0 1.0 1.0"/>
            </material>
        </visual>
        <collision>
            <origin xyz="0.13510612807427902 0.0 0.0" rpy="0 0 0"/>
            <geometry>
                <box size="0.27021225614855804 0.343624230414598 0.20341581109683535" />
            </geometry>
        </collision>
    </link>
    <joint name="Link0_Cube09" type="revolute">
       <parent link="Link0"/>
       <child  link="Cube09"/>
       <origin rpy="0 0 0" xyz="0.0 0.2630448690523886 4.328593529393753" />
       <axis xyz="0 0 1"/>
       <limit effort="0.0" lower="-3.14159" upper="3.14159" velocity="0.0"/>
    </joint>
    <link name="Cube09">
        <inertial>
            <origin xyz="0 0 0" rpy="0 0 0"/>
            <mass value="1" />
            <inertia ixx="100" ixy="0" ixz="0" iyy="100" iyz="0" izz="100" />
        </inertial>
        <visual>
            <origin xyz="0 0 0" rpy="0 0 0"/>
            <geometry>
                <box size="0 0 0" />
            </geometry>
            <material name="blue">
                <color rgba="0 0.0 1.0 1.0"/>
            </material>
        </visual>
        <collision>
            <origin xyz="0 0 0" rpy="0 0 0"/>
            <geometry>
                <box size="0 0 0" />
            </geometry>
        </collision>
    </link>
    <joint name="Cube09_Link10" type="revolute">
       <parent link="Cube09"/>
       <child  link="Link10"/>
       <origin rpy="0 0 0" xyz="0 0 0" />
       <axis xyz="1 0 0"/>
       <limit effort="0.0" lower="-3.14159" upper="3.14159" velocity="0.0"/>
    </joint>
    <link name="Link10">
        <inertial>
            <origin xyz="0.0 0.1464646835294007 0.0" rpy="0 0 0"/>
            <mass value="1" />
            <inertia ixx="100" ixy="0" ixz="0" iyy="100" iyz="0" izz="100" />
        </inertial>
        <visual>
            <origin xyz="0.0 0.1464646835294007 0.0" rpy="0 0 0"/>
            <geometry>
                <box size="0.3491528678049709 0.2929293670588014 0.30734026265718556" />
            </geometry>
            <material name="green">
                <color rgba="0 1.0 0.0 1.0"/>
            </material>
        </visual>
        <collision>
            <origin xyz="0.0 0.1464646835294007 0.0" rpy="0 0 0"/>
            <geometry>
                <box size="0.3491528678049709 0.2929293670588014 0.30734026265718556" />
            </geometry>
        </collision>
    </link>
    <joint name="Link0_Cube010" type="revolute">
       <parent link="Link0"/>
       <child  link="Cube010"/>
       <origin rpy="0 0 0" xyz="0.0 0.0 4.753648810130358" />
       <axis xyz="0 1 0"/>
       <limit effort="0.0" lower="-3.14159" upper="3.14159" velocity="0.0"/>
    </joint>
    <link name="Cube010">
        <inertial>
            <origin xyz="0 0 0" rpy="0 0 0"/>
            <mass value="1" />
            <inertia ixx="100" ixy="0" ixz="0" iyy="100" iyz="0" izz="100" />
        </inertial>
        <visual>
            <origin xyz="0 0 0" rpy="0 0 0"/>
            <geometry>
                <box size="0 0 0" />
            </geometry>
            <material name="blue">
                <color rgba="0 0.0 1.0 1.0"/>
            </material>
        </visual>
        <collision>
            <origin xyz="0 0 0" rpy="0 0 0"/>
            <geometry>
                <box size="0 0 0" />
            </geometry>
        </collision>
    </link>
    <joint name="Cube010_Cube110" type="revolute">
       <parent link="Cube010"/>
       <child  link="Cube110"/>
       <origin rpy="0 0 0" xyz="0 0 0" />
       <axis xyz="0 0 1"/>
       <limit effort="0.0" lower="-3.14159" upper="3.14159" velocity="0.0"/>
    </joint>
    <link name="Cube110">
        <inertial>
            <origin xyz="0 0 0" rpy="0 0 0"/>
            <mass value="1" />
            <inertia ixx="100" ixy="0" ixz="0" iyy="100" iyz="0" izz="100" />
        </inertial>
        <visual>
            <origin xyz="0 0 0" rpy="0 0 0"/>
            <geometry>
                <box size="0 0 0" />
            </geometry>
            <material name="blue">
                <color rgba="0 0.0 1.0 1.0"/>
            </material>
        </visual>
        <collision>
            <origin xyz="0 0 0" rpy="0 0 0"/>
            <geometry>
                <box size="0 0 0" />
            </geometry>
        </collision>
    </link>
    <joint name="Cube110_Link11" type="revolute">
       <parent link="Cube110"/>
       <child  link="Link11"/>
       <origin rpy="0 0 0" xyz="0 0 0" />
       <axis xyz="1 0 0"/>
       <limit effort="0.0" lower="-3.14159" upper="3.14159" velocity="0.0"/>
    </joint>
    <link name="Link11">
        <inertial>
            <origin xyz="0.0 0.0 0.14207646035024088" rpy="0 0 0"/>
            <mass value="1" />
            <inertia ixx="100" ixy="0" ixz="0" iyy="100" iyz="0" izz="100" />
        </inertial>
        <visual>
            <origin xyz="0.0 0.0 0.14207646035024088" rpy="0 0 0"/>
            <geometry>
                <box size="0.4060525577296106 0.4298081278702987 0.28415292070048176" />
            </geometry>
            <material name="green">
                <color rgba="0 1.0 0.0 1.0"/>
            </material>
        </visual>
        <collision>
            <origin xyz="0.0 0.0 0.14207646035024088" rpy="0 0 0"/>
            <geometry>
                <box size="0.4060525577296106 0.4298081278702987 0.28415292070048176" />
            </geometry>
        </collision>
    </link>
    <joint name="Link4_Cube011" type="revolute">
       <parent link="Link4"/>
       <child  link="Cube011"/>
       <origin rpy="0 0 0" xyz="-0.21820941225404647 0.17257990972102422 0.0" />
       <axis xyz="0 0 1"/>
       <limit effort="0.0" lower="-3.14159" upper="3.14159" velocity="0.0"/>
    </joint>
    <link name="Cube011">
        <inertial>
            <origin xyz="0 0 0" rpy="0 0 0"/>
            <mass value="1" />
            <inertia ixx="100" ixy="0" ixz="0" iyy="100" iyz="0" izz="100" />
        </inertial>
        <visual>
            <origin xyz="0 0 0" rpy="0 0 0"/>
            <geometry>
                <box size="0 0 0" />
            </geometry>
            <material name="blue">
                <color rgba="0 0.0 1.0 1.0"/>
            </material>
        </visual>
        <collision>
            <origin xyz="0 0 0" rpy="0 0 0"/>
            <geometry>
                <box size="0 0 0" />
            </geometry>
        </collision>
    </link>
    <joint name="Cube011_Link12" type="revolute">
       <parent link="Cube011"/>
       <child  link="Link12"/>
       <origin rpy="0 0 0" xyz="0 0 0" />
       <axis xyz="1 0 0"/>
       <limit effort="0.0" lower="-3.14159" upper="3.14159" velocity="0.0"/>
    </joint>
    <link name="Link12">
        <inertial>
            <origin xyz="0.0 0.15396910281409074 0.0" rpy="0 0 0"/>
            <mass value="1" />
            <inertia ixx="100" ixy="0" ixz="0" iyy="100" iyz="0" izz="100" />
        </inertial>
        <visual>
            <origin xyz="0.0 0.15396910281409074 0.0" rpy="0 0 0"/>
            <geometry>
                <box size="0.2520508184524395 0.30793820562818147 0.23974593448489384" />
            </geometry>
            <material name="blue">
                <color rgba="0 0.0 1.0 1.0"/>
            </material>
        </visual>
        <collision>
            <origin xyz="0.0 0.15396910281409074 0.0" rpy="0 0 0"/>
            <geometry>
                <box size="0.2520508184524395 0.30793820562818147 0.23974593448489384" />
            </geometry>
        </collision>
    </link>
    <joint name="Link6_Link13" type="revolute">
       <parent link="Link6"/>
       <child  link="Link13"/>
       <origin rpy="0 0 0" xyz="-0.16188301976865735 0.0 0.17640499510418134" />
       <axis xyz="0 0 1"/>
       <limit effort="0.0" lower="-3.14159" upper="3.14159" velocity="0.0"/>
    </joint>
    <link name="Link13">
        <inertial>
            <origin xyz="-0.15394801453499918 0.0 0.0" rpy="0 0 0"/>
            <mass value="1" />
            <inertia ixx="100" ixy="0" ixz="0" iyy="100" iyz="0" izz="100" />
        </inertial>
        <visual>
            <origin xyz="-0.15394801453499918 0.0 0.0" rpy="0 0 0"/>
            <geometry>
                <box size="0.30789602906999836 0.2042619486332664 0.27390768898136963" />
            </geometry>
            <material name="blue">
                <color rgba="0 0.0 1.0 1.0"/>
            </material>
        </visual>
        <collision>
            <origin xyz="-0.15394801453499918 0.0 0.0" rpy="0 0 0"/>
            <geometry>
                <box size="0.30789602906999836 0.2042619486332664 0.27390768898136963" />
            </geometry>
        </collision>
    </link>
    <joint name="Link4_Cube013" type="revolute">
       <parent link="Link4"/>
       <child  link="Cube013"/>
       <origin rpy="0 0 0" xyz="-0.21820941225404647 -0.17257990972102422 0.0" />
       <axis xyz="0 1 0"/>
       <limit effort="0.0" lower="-3.14159" upper="3.14159" velocity="0.0"/>
    </joint>
    <link name="Cube013">
        <inertial>
            <origin xyz="0 0 0" rpy="0 0 0"/>
            <mass value="1" />
            <inertia ixx="100" ixy="0" ixz="0" iyy="100" iyz="0" izz="100" />
        </inertial>
        <visual>
            <origin xyz="0 0 0" rpy="0 0 0"/>
            <geometry>
                <box size="0 0 0" />
            </geometry>
            <material name="blue">
                <color rgba="0 0.0 1.0 1.0"/>
            </material>
        </visual>
        <collision>
            <origin xyz="0 0 0" rpy="0 0 0"/>
            <geometry>
                <box size="0 0 0" />
            </geometry>
        </collision>
    </link>
    <joint name="Cube013_Cube113" type="revolute">
       <parent link="Cube013"/>
       <child  link="Cube113"/>
       <origin rpy="0 0 0" xyz="0 0 0" />
       <axis xyz="0 0 1"/>
       <limit effort="0.0" lower="-3.14159" upper="3.14159" velocity="0.0"/>
    </joint>
    <link name="Cube113">
        <inertial>
            <origin xyz="0 0 0" rpy="0 0 0"/>
            <mass value="1" />
            <inertia ixx="100" ixy="0" ixz="0" iyy="100" iyz="0" izz="100" />
        </inertial>
        <visual>
            <origin xyz="0 0 0" rpy="0 0 0"/>
            <geometry>
                <box size="0 0 0" />
            </geometry>
            <material name="blue">
                <color rgba="0 0.0 1.0 1.0"/>
            </material>
        </visual>
        <collision>
            <origin xyz="0 0 0" rpy="0 0 0"/>
            <geometry>
                <box size="0 0 0" />
            </geometry>
        </collision>
    </link>
    <joint name="Cube113_Link14" type="revolute">
       <parent link="Cube113"/>
       <child  link="Link14"/>
       <origin rpy="0 0 0" xyz="0 0 0" />
       <axis xyz="1 0 0"/>
       <limit effort="0.0" lower="-3.14159" upper="3.14159" velocity="0.0"/>
    </joint>
    <link name="Link14">
        <inertial>
            <origin xyz="0.0 -0.11878509800039883 0.0" rpy="0 0 0"/>
            <mass value="1" />
            <inertia ixx="100" ixy="0" ixz="0" iyy="100" iyz="0" izz="100" />
        </inertial>
        <visual>
            <origin xyz="0.0 -0.11878509800039883 0.0" rpy="0 0 0"/>
            <geometry>
                <box size="0.2775203973593307 0.23757019600079765 0.2575895986795665" />
            </geometry>
            <material name="blue">
                <color rgba="0 0.0 1.0 1.0"/>
            </material>
        </visual>
        <collision>
            <origin xyz="0.0 -0.11878509800039883 0.0" rpy="0 0 0"/>
            <geometry>
                <box size="0.2775203973593307 0.23757019600079765 0.2575895986795665" />
            </geometry>
        </collision>
    </link>
</robot>