<robot name = "robot">
    <link name="Link0">
        <inertial>
            <origin xyz="0 0 2.2649391571744446" rpy="0 0 0"/>
            <mass value="1" />
            <inertia ixx="100" ixy="0" ixz="0" iyy="100" iyz="0" izz="100" />
        </inertial>
        <visual>
            <origin xyz="0 0 2.2649391571744446" rpy="0 0 0"/>
            <geometry>
                <box size="0.35488175546841455 0.9279967323477336 0.862388237485695" />
            </geometry>
            <material name="blue">
                <color rgba="0 0.0 1.0 1.0"/>
            </material>
        </visual>
        <collision>
            <origin xyz="0 0 2.2649391571744446" rpy="0 0 0"/>
            <geometry>
                <box size="0.35488175546841455 0.9279967323477336 0.862388237485695" />
            </geometry>
        </collision>
    </link>
    <joint name="Link0_Cube00" type="revolute">
       <parent link="Link0"/>
       <child  link="Cube00"/>
       <origin rpy="0 0 0" xyz="0.0 -0.4639983661738668 2.2649391571744446" />
       <axis xyz="0 0 1"/>
       <limit effort="0.0" lower="-3.14159" upper="3.14159" velocity="0.0"/>
    </joint>
    <link name="Cube00">
        <inertial>
            <origin xyz="0 0 0" rpy="0 0 0"/>
            <mass value="1" />
            <inertia ixx="100" ixy="0" ixz="0" iyy="100" iyz="0" izz="100" />
        </inertial>
        <visual>
            <origin xyz="0 0 0" rpy="0 0 0"/>
            <geometry>
                <box size="0 0 0" />
            </geometry>
            <material name="blue">
                <color rgba="0 0.0 1.0 1.0"/>
            </material>
        </visual>
        <collision>
            <origin xyz="0 0 0" rpy="0 0 0"/>
            <geometry>
                <box size="0 0 0" />
            </geometry>
        </collision>
    </link>
    <joint name="Cube00_Link1" type="revolute">
       <parent link="Cube00"/>
       <child  link="Link1"/>
       <origin rpy="0 0 0" xyz="0 0 0" />
       <axis xyz="0 1 0"/>
       <limit effort="0.0" lower="-3.14159" upper="3.14159" velocity="0.0"/>
    </joint>
    <link name="Link1">
        <inertial>
            <origin xyz="0.0 -0.3148943916492378 0.0" rpy="0 0 0"/>
            <mass value="1" />
            <inertia ixx="100" ixy="0" ixz="0" iyy="100" iyz="0" izz="100" />
        </inertial>
        <visual>
            <origin xyz="0.0 -0.3148943916492378 0.0" rpy="0 0 0"/>
            <geometry>
                <box size="0.54087982638983 0.6297887832984757 0.2346412427981469" />
            </geometry>
            <material name="green">
                <color rgba="0 1.0 0.0 1.0"/>
            </material>
        </visual>
        <collision>
            <origin xyz="0.0 -0.3148943916492378 0.0" rpy="0 0 0"/>
            <geometry>
                <box size="0.54087982638983 0.6297887832984757 0.2346412427981469" />
            </geometry>
        </collision>
    </link>
    <joint name="Link0_Cube01" type="revolute">
       <parent link="Link0"/>
       <child  link="Cube01"/>
       <origin rpy="0 0 0" xyz="0.0 0.0 1.833745038431597" />
       <axis xyz="0 0 1"/>
       <limit effort="0.0" lower="-3.14159" upper="3.14159" velocity="0.0"/>
    </joint>
    <link name="Cube01">
        <inertial>
            <origin xyz="0 0 0" rpy="0 0 0"/>
            <mass value="1" />
            <inertia ixx="100" ixy="0" ixz="0" iyy="100" iyz="0" izz="100" />
        </inertial>
        <visual>
            <origin xyz="0 0 0" rpy="0 0 0"/>
            <geometry>
                <box size="0 0 0" />
            </geometry>
            <material name="blue">
                <color rgba="0 0.0 1.0 1.0"/>
            </material>
        </visual>
        <collision>
            <origin xyz="0 0 0" rpy="0 0 0"/>
            <geometry>
                <box size="0 0 0" />
            </geometry>
        </collision>
    </link>
    <joint name="Cube01_Link2" type="revolute">
       <parent link="Cube01"/>
       <child  link="Link2"/>
       <origin rpy="0 0 0" xyz="0 0 0" />
       <axis xyz="1 0 0"/>
       <limit effort="0.0" lower="-3.14159" upper="3.14159" velocity="0.0"/>
    </joint>
    <link name="Link2">
        <inertial>
            <origin xyz="0.0 0.0 -0.17670748875687173" rpy="0 0 0"/>
            <mass value="1" />
            <inertia ixx="100" ixy="0" ixz="0" iyy="100" iyz="0" izz="100" />
        </inertial>
        <visual>
            <origin xyz="0.0 0.0 -0.17670748875687173" rpy="0 0 0"/>
            <geometry>
                <box size="0.2658990204940399 0.20663256730952836 0.35341497751374346" />
            </geometry>
            <material name="green">
                <color rgba="0 1.0 0.0 1.0"/>
            </material>
        </visual>
        <collision>
            <origin xyz="0.0 0.0 -0.17670748875687173" rpy="0 0 0"/>
            <geometry>
                <box size="0.2658990204940399 0.20663256730952836 0.35341497751374346" />
            </geometry>
        </collision>
    </link>
    <joint name="Link0_Cube02" type="revolute">
       <parent link="Link0"/>
       <child  link="Cube02"/>
       <origin rpy="0 0 0" xyz="0.0 0.4639983661738668 2.2649391571744446" />
       <axis xyz="0 0 1"/>
       <limit effort="0.0" lower="-3.14159" upper="3.14159" velocity="0.0"/>
    </joint>
    <link name="Cube02">
        <inertial>
            <origin xyz="0 0 0" rpy="0 0 0"/>
            <mass value="1" />
            <inertia ixx="100" ixy="0" ixz="0" iyy="100" iyz="0" izz="100" />
        </inertial>
        <visual>
            <origin xyz="0 0 0" rpy="0 0 0"/>
            <geometry>
                <box size="0 0 0" />
            </geometry>
            <material name="blue">
                <color rgba="0 0.0 1.0 1.0"/>
            </material>
        </visual>
        <collision>
            <origin xyz="0 0 0" rpy="0 0 0"/>
            <geometry>
                <box size="0 0 0" />
            </geometry>
        </collision>
    </link>
    <joint name="Cube02_Link3" type="revolute">
       <parent link="Cube02"/>
       <child  link="Link3"/>
       <origin rpy="0 0 0" xyz="0 0 0" />
       <axis xyz="1 0 0"/>
       <limit effort="0.0" lower="-3.14159" upper="3.14159" velocity="0.0"/>
    </joint>
    <link name="Link3">
        <inertial>
            <origin xyz="0.0 0.256510460797547 0.0" rpy="0 0 0"/>
            <mass value="1" />
            <inertia ixx="100" ixy="0" ixz="0" iyy="100" iyz="0" izz="100" />
        </inertial>
        <visual>
            <origin xyz="0.0 0.256510460797547 0.0" rpy="0 0 0"/>
            <geometry>
                <box size="0.2830379391250262 0.513020921595094 0.5628482020116587" />
            </geometry>
            <material name="blue">
                <color rgba="0 0.0 1.0 1.0"/>
            </material>
        </visual>
        <collision>
            <origin xyz="0.0 0.256510460797547 0.0" rpy="0 0 0"/>
            <geometry>
                <box size="0.2830379391250262 0.513020921595094 0.5628482020116587" />
            </geometry>
        </collision>
    </link>
    <joint name="Link3_Cube03" type="revolute">
       <parent link="Link3"/>
       <child  link="Cube03"/>
       <origin rpy="0 0 0" xyz="0.0 0.256510460797547 -0.2814241010058294" />
       <axis xyz="1 0 0"/>
       <limit effort="0.0" lower="-3.14159" upper="3.14159" velocity="0.0"/>
    </joint>
    <link name="Cube03">
        <inertial>
            <origin xyz="0 0 0" rpy="0 0 0"/>
            <mass value="1" />
            <inertia ixx="100" ixy="0" ixz="0" iyy="100" iyz="0" izz="100" />
        </inertial>
        <visual>
            <origin xyz="0 0 0" rpy="0 0 0"/>
            <geometry>
                <box size="0 0 0" />
            </geometry>
            <material name="blue">
                <color rgba="0 0.0 1.0 1.0"/>
            </material>
        </visual>
        <collision>
            <origin xyz="0 0 0" rpy="0 0 0"/>
            <geometry>
                <box size="0 0 0" />
            </geometry>
        </collision>
    </link>
    <joint name="Cube03_Cube13" type="revolute">
       <parent link="Cube03"/>
       <child  link="Cube13"/>
       <origin rpy="0 0 0" xyz="0 0 0" />
       <axis xyz="0 0 1"/>
       <limit effort="0.0" lower="-3.14159" upper="3.14159" velocity="0.0"/>
    </joint>
    <link name="Cube13">
        <inertial>
            <origin xyz="0 0 0" rpy="0 0 0"/>
            <mass value="1" />
            <inertia ixx="100" ixy="0" ixz="0" iyy="100" iyz="0" izz="100" />
        </inertial>
        <visual>
            <origin xyz="0 0 0" rpy="0 0 0"/>
            <geometry>
                <box size="0 0 0" />
            </geometry>
            <material name="blue">
                <color rgba="0 0.0 1.0 1.0"/>
            </material>
        </visual>
        <collision>
            <origin xyz="0 0 0" rpy="0 0 0"/>
            <geometry>
                <box size="0 0 0" />
            </geometry>
        </collision>
    </link>
    <joint name="Cube13_Link4" type="revolute">
       <parent link="Cube13"/>
       <child  link="Link4"/>
       <origin rpy="0 0 0" xyz="0 0 0" />
       <axis xyz="0 1 0"/>
       <limit effort="0.0" lower="-3.14159" upper="3.14159" velocity="0.0"/>
    </joint>
    <link name="Link4">
        <inertial>
            <origin xyz="0.0 0.0 -0.2294241497231326" rpy="0 0 0"/>
            <mass value="1" />
            <inertia ixx="100" ixy="0" ixz="0" iyy="100" iyz="0" izz="100" />
        </inertial>
        <visual>
            <origin xyz="0.0 0.0 -0.2294241497231326" rpy="0 0 0"/>
            <geometry>
                <box size="0.38950013081226775 0.39627449819178695 0.4588482994462652" />
            </geometry>
            <material name="blue">
                <color rgba="0 0.0 1.0 1.0"/>
            </material>
        </visual>
        <collision>
            <origin xyz="0.0 0.0 -0.2294241497231326" rpy="0 0 0"/>
            <geometry>
                <box size="0.38950013081226775 0.39627449819178695 0.4588482994462652" />
            </geometry>
        </collision>
    </link>
    <joint name="Link1_Cube04" type="revolute">
       <parent link="Link1"/>
       <child  link="Cube04"/>
       <origin rpy="0 0 0" xyz="-0.270439913194915 -0.3148943916492378 0.0" />
       <axis xyz="0 0 1"/>
       <limit effort="0.0" lower="-3.14159" upper="3.14159" velocity="0.0"/>
    </joint>
    <link name="Cube04">
        <inertial>
            <origin xyz="0 0 0" rpy="0 0 0"/>
            <mass value="1" />
            <inertia ixx="100" ixy="0" ixz="0" iyy="100" iyz="0" izz="100" />
        </inertial>
        <visual>
            <origin xyz="0 0 0" rpy="0 0 0"/>
            <geometry>
                <box size="0 0 0" />
            </geometry>
            <material name="blue">
                <color rgba="0 0.0 1.0 1.0"/>
            </material>
        </visual>
        <collision>
            <origin xyz="0 0 0" rpy="0 0 0"/>
            <geometry>
                <box size="0 0 0" />
            </geometry>
        </collision>
    </link>
    <joint name="Cube04_Link5" type="revolute">
       <parent link="Cube04"/>
       <child  link="Link5"/>
       <origin rpy="0 0 0" xyz="0 0 0" />
       <axis xyz="0 1 0"/>
       <limit effort="0.0" lower="-3.14159" upper="3.14159" velocity="0.0"/>
    </joint>
    <link name="Link5">
        <inertial>
            <origin xyz="-0.21546256065819072 0.0 0.0" rpy="0 0 0"/>
            <mass value="1" />
            <inertia ixx="100" ixy="0" ixz="0" iyy="100" iyz="0" izz="100" />
        </inertial>
        <visual>
            <origin xyz="-0.21546256065819072 0.0 0.0" rpy="0 0 0"/>
            <geometry>
                <box size="0.43092512131638144 0.2506616357492104 0.22238097141402077" />
            </geometry>
            <material name="green">
                <color rgba="0 1.0 0.0 1.0"/>
            </material>
        </visual>
        <collision>
            <origin xyz="-0.21546256065819072 0.0 0.0" rpy="0 0 0"/>
            <geometry>
                <box size="0.43092512131638144 0.2506616357492104 0.22238097141402077" />
            </geometry>
        </collision>
    </link>
    <joint name="Link0_Link6" type="revolute">
       <parent link="Link0"/>
       <child  link="Link6"/>
       <origin rpy="0 0 0" xyz="0.0 0.0 2.6961332759172922" />
       <axis xyz="0 0 1"/>
       <limit effort="0.0" lower="-3.14159" upper="3.14159" velocity="0.0"/>
    </joint>
    <link name="Link6">
        <inertial>
            <origin xyz="0.0 0.0 0.3979423610784183" rpy="0 0 0"/>
            <mass value="1" />
            <inertia ixx="100" ixy="0" ixz="0" iyy="100" iyz="0" izz="100" />
        </inertial>
        <visual>
            <origin xyz="0.0 0.0 0.3979423610784183" rpy="0 0 0"/>
            <geometry>
                <box size="0.2446194907857513 0.6324029385790011 0.7958847221568366" />
            </geometry>
            <material name="blue">
                <color rgba="0 0.0 1.0 1.0"/>
            </material>
        </visual>
        <collision>
            <origin xyz="0.0 0.0 0.3979423610784183" rpy="0 0 0"/>
            <geometry>
                <box size="0.2446194907857513 0.6324029385790011 0.7958847221568366" />
            </geometry>
        </collision>
    </link>
</robot>