<robot name = "robot">
    <link name="Link0">
        <inertial>
            <origin xyz="0 0 1.003213210455775" rpy="0 0 0"/>
            <mass value="1" />
            <inertia ixx="100" ixy="0" ixz="0" iyy="100" iyz="0" izz="100" />
        </inertial>
        <visual>
            <origin xyz="0 0 1.003213210455775" rpy="0 0 0"/>
            <geometry>
                <box size="0.21797655659666537 0.30661465479737854 0.20300222519170355" />
            </geometry>
            <material name="blue">
                <color rgba="0 0.0 1.0 1.0"/>
            </material>
        </visual>
        <collision>
            <origin xyz="0 0 1.003213210455775" rpy="0 0 0"/>
            <geometry>
                <box size="0.21797655659666537 0.30661465479737854 0.20300222519170355" />
            </geometry>
        </collision>
    </link>
    <joint name="Link0_Link1" type="revolute">
       <parent link="Link0"/>
       <child  link="Link1"/>
       <origin rpy="0 0 0" xyz="0.0 -0.15330732739868927 1.003213210455775" />
       <axis xyz="1 0 0"/>
       <limit effort="0.0" lower="-3.14159" upper="3.14159" velocity="0.0"/>
    </joint>
    <link name="Link1">
        <inertial>
            <origin xyz="0.0 -0.1449546092448043 0.0" rpy="0 0 0"/>
            <mass value="1" />
            <inertia ixx="100" ixy="0" ixz="0" iyy="100" iyz="0" izz="100" />
        </inertial>
        <visual>
            <origin xyz="0.0 -0.1449546092448043 0.0" rpy="0 0 0"/>
            <geometry>
                <box size="0.241553834866994 0.2899092184896086 0.2548889813521618" />
            </geometry>
            <material name="green">
                <color rgba="0 1.0 0.0 1.0"/>
            </material>
        </visual>
        <collision>
            <origin xyz="0.0 -0.1449546092448043 0.0" rpy="0 0 0"/>
            <geometry>
                <box size="0.241553834866994 0.2899092184896086 0.2548889813521618" />
            </geometry>
        </collision>
    </link>
    <joint name="Link1_Link2" type="revolute">
       <parent link="Link1"/>
       <child  link="Link2"/>
       <origin rpy="0 0 0" xyz="-0.120776917433497 -0.1449546092448043 0.0" />
       <axis xyz="0 0 1"/>
       <limit effort="0.0" lower="-3.14159" upper="3.14159" velocity="0.0"/>
    </joint>
    <link name="Link2">
        <inertial>
            <origin xyz="-0.10425201056472658 0.0 0.0" rpy="0 0 0"/>
            <mass value="1" />
            <inertia ixx="100" ixy="0" ixz="0" iyy="100" iyz="0" izz="100" />
        </inertial>
        <visual>
            <origin xyz="-0.10425201056472658 0.0 0.0" rpy="0 0 0"/>
            <geometry>
                <box size="0.20850402112945315 0.2240112589222691 0.2074069842706302" />
            </geometry>
            <material name="blue">
                <color rgba="0 0.0 1.0 1.0"/>
            </material>
        </visual>
        <collision>
            <origin xyz="-0.10425201056472658 0.0 0.0" rpy="0 0 0"/>
            <geometry>
                <box size="0.20850402112945315 0.2240112589222691 0.2074069842706302" />
            </geometry>
        </collision>
    </link>
    <joint name="Link1_Cube02" type="revolute">
       <parent link="Link1"/>
       <child  link="Cube02"/>
       <origin rpy="0 0 0" xyz="0.0 -0.1449546092448043 -0.1274444906760809" />
       <axis xyz="0 1 0"/>
       <limit effort="0.0" lower="-3.14159" upper="3.14159" velocity="0.0"/>
    </joint>
    <link name="Cube02">
        <inertial>
            <origin xyz="0 0 0" rpy="0 0 0"/>
            <mass value="1" />
            <inertia ixx="100" ixy="0" ixz="0" iyy="100" iyz="0" izz="100" />
        </inertial>
        <visual>
            <origin xyz="0 0 0" rpy="0 0 0"/>
            <geometry>
                <box size="0 0 0" />
            </geometry>
            <material name="blue">
                <color rgba="0 0.0 1.0 1.0"/>
            </material>
        </visual>
        <collision>
            <origin xyz="0 0 0" rpy="0 0 0"/>
            <geometry>
                <box size="0 0 0" />
            </geometry>
        </collision>
    </link>
    <joint name="Cube02_Cube12" type="revolute">
       <parent link="Cube02"/>
       <child  link="Cube12"/>
       <origin rpy="0 0 0" xyz="0 0 0" />
       <axis xyz="1 0 0"/>
       <limit effort="0.0" lower="-3.14159" upper="3.14159" velocity="0.0"/>
    </joint>
    <link name="Cube12">
        <inertial>
            <origin xyz="0 0 0" rpy="0 0 0"/>
            <mass value="1" />
            <inertia ixx="100" ixy="0" ixz="0" iyy="100" iyz="0" izz="100" />
        </inertial>
        <visual>
            <origin xyz="0 0 0" rpy="0 0 0"/>
            <geometry>
                <box size="0 0 0" />
            </geometry>
            <material name="blue">
                <color rgba="0 0.0 1.0 1.0"/>
            </material>
        </visual>
        <collision>
            <origin xyz="0 0 0" rpy="0 0 0"/>
            <geometry>
                <box size="0 0 0" />
            </geometry>
        </collision>
    </link>
    <joint name="Cube12_Link3" type="revolute">
       <parent link="Cube12"/>
       <child  link="Link3"/>
       <origin rpy="0 0 0" xyz="0 0 0" />
       <axis xyz="0 0 1"/>
       <limit effort="0.0" lower="-3.14159" upper="3.14159" velocity="0.0"/>
    </joint>
    <link name="Link3">
        <inertial>
            <origin xyz="0.0 0.0 -0.10403285736679453" rpy="0 0 0"/>
            <mass value="1" />
            <inertia ixx="100" ixy="0" ixz="0" iyy="100" iyz="0" izz="100" />
        </inertial>
        <visual>
            <origin xyz="0.0 0.0 -0.10403285736679453" rpy="0 0 0"/>
            <geometry>
                <box size="0.20746756725076176 0.22334313608696502 0.20806571473358906" />
            </geometry>
            <material name="green">
                <color rgba="0 1.0 0.0 1.0"/>
            </material>
        </visual>
        <collision>
            <origin xyz="0.0 0.0 -0.10403285736679453" rpy="0 0 0"/>
            <geometry>
                <box size="0.20746756725076176 0.22334313608696502 0.20806571473358906" />
            </geometry>
        </collision>
    </link>
</robot>