<robot name = "robot">
    <link name="Link0">
        <inertial>
            <origin xyz="0 0 1.2374864679501025" rpy="0 0 0"/>
            <mass value="1" />
            <inertia ixx="100" ixy="0" ixz="0" iyy="100" iyz="0" izz="100" />
        </inertial>
        <visual>
            <origin xyz="0 0 1.2374864679501025" rpy="0 0 0"/>
            <geometry>
                <box size="0.4970504878735181 0.6251692217253799 0.5817337298242583" />
            </geometry>
            <material name="blue">
                <color rgba="0 0.0 1.0 1.0"/>
            </material>
        </visual>
        <collision>
            <origin xyz="0 0 1.2374864679501025" rpy="0 0 0"/>
            <geometry>
                <box size="0.4970504878735181 0.6251692217253799 0.5817337298242583" />
            </geometry>
        </collision>
    </link>
    <joint name="Link0_Link1" type="revolute">
       <parent link="Link0"/>
       <child  link="Link1"/>
       <origin rpy="0 0 0" xyz="0.0 -0.31258461086268996 1.2374864679501025" />
       <axis xyz="0 1 0"/>
       <limit effort="0.0" lower="-3.14159" upper="3.14159" velocity="0.0"/>
    </joint>
    <link name="Link1">
        <inertial>
            <origin xyz="0.0 -0.30837960969651657 0.0" rpy="0 0 0"/>
            <mass value="1" />
            <inertia ixx="100" ixy="0" ixz="0" iyy="100" iyz="0" izz="100" />
        </inertial>
        <visual>
            <origin xyz="0.0 -0.30837960969651657 0.0" rpy="0 0 0"/>
            <geometry>
                <box size="0.6016541779292256 0.6167592193930331 0.45175242820454536" />
            </geometry>
            <material name="blue">
                <color rgba="0 0.0 1.0 1.0"/>
            </material>
        </visual>
        <collision>
            <origin xyz="0.0 -0.30837960969651657 0.0" rpy="0 0 0"/>
            <geometry>
                <box size="0.6016541779292256 0.6167592193930331 0.45175242820454536" />
            </geometry>
        </collision>
    </link>
    <joint name="Link1_Link2" type="revolute">
       <parent link="Link1"/>
       <child  link="Link2"/>
       <origin rpy="0 0 0" xyz="0.0 -0.6167592193930331 0.0" />
       <axis xyz="0 1 0"/>
       <limit effort="0.0" lower="-3.14159" upper="3.14159" velocity="0.0"/>
    </joint>
    <link name="Link2">
        <inertial>
            <origin xyz="0.0 -0.27834805197258167 0.0" rpy="0 0 0"/>
            <mass value="1" />
            <inertia ixx="100" ixy="0" ixz="0" iyy="100" iyz="0" izz="100" />
        </inertial>
        <visual>
            <origin xyz="0.0 -0.27834805197258167 0.0" rpy="0 0 0"/>
            <geometry>
                <box size="0.3338948477012774 0.5566961039451633 0.3252232958867596" />
            </geometry>
            <material name="green">
                <color rgba="0 1.0 0.0 1.0"/>
            </material>
        </visual>
        <collision>
            <origin xyz="0.0 -0.27834805197258167 0.0" rpy="0 0 0"/>
            <geometry>
                <box size="0.3338948477012774 0.5566961039451633 0.3252232958867596" />
            </geometry>
        </collision>
    </link>
</robot>