<robot name = "robot">
    <link name="Link0">
        <inertial>
            <origin xyz="0 0 3.35242132411057" rpy="0 0 0"/>
            <mass value="1" />
            <inertia ixx="100" ixy="0" ixz="0" iyy="100" iyz="0" izz="100" />
        </inertial>
        <visual>
            <origin xyz="0 0 3.35242132411057" rpy="0 0 0"/>
            <geometry>
                <box size="0.6662706579309006 0.2588161478529511 0.8624804148084042" />
            </geometry>
            <material name="blue">
                <color rgba="0 0.0 1.0 1.0"/>
            </material>
        </visual>
        <collision>
            <origin xyz="0 0 3.35242132411057" rpy="0 0 0"/>
            <geometry>
                <box size="0.6662706579309006 0.2588161478529511 0.8624804148084042" />
            </geometry>
        </collision>
    </link>
    <joint name="Link0_Cube00" type="revolute">
       <parent link="Link0"/>
       <child  link="Cube00"/>
       <origin rpy="0 0 0" xyz="0.0 0.0 2.921181116706368" />
       <axis xyz="0 1 0"/>
       <limit effort="0.0" lower="-3.14159" upper="3.14159" velocity="0.0"/>
    </joint>
    <link name="Cube00">
        <inertial>
            <origin xyz="0 0 0" rpy="0 0 0"/>
            <mass value="1" />
            <inertia ixx="100" ixy="0" ixz="0" iyy="100" iyz="0" izz="100" />
        </inertial>
        <visual>
            <origin xyz="0 0 0" rpy="0 0 0"/>
            <geometry>
                <box size="0 0 0" />
            </geometry>
            <material name="blue">
                <color rgba="0 0.0 1.0 1.0"/>
            </material>
        </visual>
        <collision>
            <origin xyz="0 0 0" rpy="0 0 0"/>
            <geometry>
                <box size="0 0 0" />
            </geometry>
        </collision>
    </link>
    <joint name="Cube00_Link1" type="revolute">
       <parent link="Cube00"/>
       <child  link="Link1"/>
       <origin rpy="0 0 0" xyz="0 0 0" />
       <axis xyz="1 0 0"/>
       <limit effort="0.0" lower="-3.14159" upper="3.14159" velocity="0.0"/>
    </joint>
    <link name="Link1">
        <inertial>
            <origin xyz="0.0 0.0 -0.18421262442351521" rpy="0 0 0"/>
            <mass value="1" />
            <inertia ixx="100" ixy="0" ixz="0" iyy="100" iyz="0" izz="100" />
        </inertial>
        <visual>
            <origin xyz="0.0 0.0 -0.18421262442351521" rpy="0 0 0"/>
            <geometry>
                <box size="0.28757697246624236 0.23505408354144688 0.36842524884703043" />
            </geometry>
            <material name="blue">
                <color rgba="0 0.0 1.0 1.0"/>
            </material>
        </visual>
        <collision>
            <origin xyz="0.0 0.0 -0.18421262442351521" rpy="0 0 0"/>
            <geometry>
                <box size="0.28757697246624236 0.23505408354144688 0.36842524884703043" />
            </geometry>
        </collision>
    </link>
    <joint name="Link0_Link2" type="revolute">
       <parent link="Link0"/>
       <child  link="Link2"/>
       <origin rpy="0 0 0" xyz="0.0 0.0 3.783661531514772" />
       <axis xyz="0 0 1"/>
       <limit effort="0.0" lower="-3.14159" upper="3.14159" velocity="0.0"/>
    </joint>
    <link name="Link2">
        <inertial>
            <origin xyz="0.0 0.0 0.3275421778188776" rpy="0 0 0"/>
            <mass value="1" />
            <inertia ixx="100" ixy="0" ixz="0" iyy="100" iyz="0" izz="100" />
        </inertial>
        <visual>
            <origin xyz="0.0 0.0 0.3275421778188776" rpy="0 0 0"/>
            <geometry>
                <box size="0.46931255245003467 0.6830045972709933 0.6550843556377552" />
            </geometry>
            <material name="green">
                <color rgba="0 1.0 0.0 1.0"/>
            </material>
        </visual>
        <collision>
            <origin xyz="0.0 0.0 0.3275421778188776" rpy="0 0 0"/>
            <geometry>
                <box size="0.46931255245003467 0.6830045972709933 0.6550843556377552" />
            </geometry>
        </collision>
    </link>
    <joint name="Link0_Cube02" type="revolute">
       <parent link="Link0"/>
       <child  link="Cube02"/>
       <origin rpy="0 0 0" xyz="0.3331353289654503 0.0 3.35242132411057" />
       <axis xyz="0 0 1"/>
       <limit effort="0.0" lower="-3.14159" upper="3.14159" velocity="0.0"/>
    </joint>
    <link name="Cube02">
        <inertial>
            <origin xyz="0 0 0" rpy="0 0 0"/>
            <mass value="1" />
            <inertia ixx="100" ixy="0" ixz="0" iyy="100" iyz="0" izz="100" />
        </inertial>
        <visual>
            <origin xyz="0 0 0" rpy="0 0 0"/>
            <geometry>
                <box size="0 0 0" />
            </geometry>
            <material name="blue">
                <color rgba="0 0.0 1.0 1.0"/>
            </material>
        </visual>
        <collision>
            <origin xyz="0 0 0" rpy="0 0 0"/>
            <geometry>
                <box size="0 0 0" />
            </geometry>
        </collision>
    </link>
    <joint name="Cube02_Cube12" type="revolute">
       <parent link="Cube02"/>
       <child  link="Cube12"/>
       <origin rpy="0 0 0" xyz="0 0 0" />
       <axis xyz="0 1 0"/>
       <limit effort="0.0" lower="-3.14159" upper="3.14159" velocity="0.0"/>
    </joint>
    <link name="Cube12">
        <inertial>
            <origin xyz="0 0 0" rpy="0 0 0"/>
            <mass value="1" />
            <inertia ixx="100" ixy="0" ixz="0" iyy="100" iyz="0" izz="100" />
        </inertial>
        <visual>
            <origin xyz="0 0 0" rpy="0 0 0"/>
            <geometry>
                <box size="0 0 0" />
            </geometry>
            <material name="blue">
                <color rgba="0 0.0 1.0 1.0"/>
            </material>
        </visual>
        <collision>
            <origin xyz="0 0 0" rpy="0 0 0"/>
            <geometry>
                <box size="0 0 0" />
            </geometry>
        </collision>
    </link>
    <joint name="Cube12_Link3" type="revolute">
       <parent link="Cube12"/>
       <child  link="Link3"/>
       <origin rpy="0 0 0" xyz="0 0 0" />
       <axis xyz="1 0 0"/>
       <limit effort="0.0" lower="-3.14159" upper="3.14159" velocity="0.0"/>
    </joint>
    <link name="Link3">
        <inertial>
            <origin xyz="0.32609306017745965 0.0 0.0" rpy="0 0 0"/>
            <mass value="1" />
            <inertia ixx="100" ixy="0" ixz="0" iyy="100" iyz="0" izz="100" />
        </inertial>
        <visual>
            <origin xyz="0.32609306017745965 0.0 0.0" rpy="0 0 0"/>
            <geometry>
                <box size="0.6521861203549193 0.32260704527149225 0.46611580701491695" />
            </geometry>
            <material name="green">
                <color rgba="0 1.0 0.0 1.0"/>
            </material>
        </visual>
        <collision>
            <origin xyz="0.32609306017745965 0.0 0.0" rpy="0 0 0"/>
            <geometry>
                <box size="0.6521861203549193 0.32260704527149225 0.46611580701491695" />
            </geometry>
        </collision>
    </link>
    <joint name="Link2_Cube03" type="revolute">
       <parent link="Link2"/>
       <child  link="Cube03"/>
       <origin rpy="0 0 0" xyz="0.0 0.34150229863549664 0.3275421778188776" />
       <axis xyz="1 0 0"/>
       <limit effort="0.0" lower="-3.14159" upper="3.14159" velocity="0.0"/>
    </joint>
    <link name="Cube03">
        <inertial>
            <origin xyz="0 0 0" rpy="0 0 0"/>
            <mass value="1" />
            <inertia ixx="100" ixy="0" ixz="0" iyy="100" iyz="0" izz="100" />
        </inertial>
        <visual>
            <origin xyz="0 0 0" rpy="0 0 0"/>
            <geometry>
                <box size="0 0 0" />
            </geometry>
            <material name="blue">
                <color rgba="0 0.0 1.0 1.0"/>
            </material>
        </visual>
        <collision>
            <origin xyz="0 0 0" rpy="0 0 0"/>
            <geometry>
                <box size="0 0 0" />
            </geometry>
        </collision>
    </link>
    <joint name="Cube03_Link4" type="revolute">
       <parent link="Cube03"/>
       <child  link="Link4"/>
       <origin rpy="0 0 0" xyz="0 0 0" />
       <axis xyz="0 0 1"/>
       <limit effort="0.0" lower="-3.14159" upper="3.14159" velocity="0.0"/>
    </joint>
    <link name="Link4">
        <inertial>
            <origin xyz="0.0 0.3128779826696764 0.0" rpy="0 0 0"/>
            <mass value="1" />
            <inertia ixx="100" ixy="0" ixz="0" iyy="100" iyz="0" izz="100" />
        </inertial>
        <visual>
            <origin xyz="0.0 0.3128779826696764 0.0" rpy="0 0 0"/>
            <geometry>
                <box size="0.23384623044592284 0.6257559653393528 0.5244792500351625" />
            </geometry>
            <material name="blue">
                <color rgba="0 0.0 1.0 1.0"/>
            </material>
        </visual>
        <collision>
            <origin xyz="0.0 0.3128779826696764 0.0" rpy="0 0 0"/>
            <geometry>
                <box size="0.23384623044592284 0.6257559653393528 0.5244792500351625" />
            </geometry>
        </collision>
    </link>
    <joint name="Link0_Link5" type="revolute">
       <parent link="Link0"/>
       <child  link="Link5"/>
       <origin rpy="0 0 0" xyz="-0.3331353289654503 0.0 3.35242132411057" />
       <axis xyz="1 0 0"/>
       <limit effort="0.0" lower="-3.14159" upper="3.14159" velocity="0.0"/>
    </joint>
    <link name="Link5">
        <inertial>
            <origin xyz="-0.31548987489556224 0.0 0.0" rpy="0 0 0"/>
            <mass value="1" />
            <inertia ixx="100" ixy="0" ixz="0" iyy="100" iyz="0" izz="100" />
        </inertial>
        <visual>
            <origin xyz="-0.31548987489556224 0.0 0.0" rpy="0 0 0"/>
            <geometry>
                <box size="0.6309797497911245 0.3760688390642617 0.25319242428980104" />
            </geometry>
            <material name="green">
                <color rgba="0 1.0 0.0 1.0"/>
            </material>
        </visual>
        <collision>
            <origin xyz="-0.31548987489556224 0.0 0.0" rpy="0 0 0"/>
            <geometry>
                <box size="0.6309797497911245 0.3760688390642617 0.25319242428980104" />
            </geometry>
        </collision>
    </link>
    <joint name="Link2_Link6" type="revolute">
       <parent link="Link2"/>
       <child  link="Link6"/>
       <origin rpy="0 0 0" xyz="0.0 0.0 0.6550843556377552" />
       <axis xyz="0 0 1"/>
       <limit effort="0.0" lower="-3.14159" upper="3.14159" velocity="0.0"/>
    </joint>
    <link name="Link6">
        <inertial>
            <origin xyz="0.0 0.0 0.24284788065434457" rpy="0 0 0"/>
            <mass value="1" />
            <inertia ixx="100" ixy="0" ixz="0" iyy="100" iyz="0" izz="100" />
        </inertial>
        <visual>
            <origin xyz="0.0 0.0 0.24284788065434457" rpy="0 0 0"/>
            <geometry>
                <box size="0.509557175920607 0.2683176352540998 0.48569576130868913" />
            </geometry>
            <material name="blue">
                <color rgba="0 0.0 1.0 1.0"/>
            </material>
        </visual>
        <collision>
            <origin xyz="0.0 0.0 0.24284788065434457" rpy="0 0 0"/>
            <geometry>
                <box size="0.509557175920607 0.2683176352540998 0.48569576130868913" />
            </geometry>
        </collision>
    </link>
    <joint name="Link3_Cube06" type="revolute">
       <parent link="Link3"/>
       <child  link="Cube06"/>
       <origin rpy="0 0 0" xyz="0.32609306017745965 0.0 -0.23305790350745847" />
       <axis xyz="1 0 0"/>
       <limit effort="0.0" lower="-3.14159" upper="3.14159" velocity="0.0"/>
    </joint>
    <link name="Cube06">
        <inertial>
            <origin xyz="0 0 0" rpy="0 0 0"/>
            <mass value="1" />
            <inertia ixx="100" ixy="0" ixz="0" iyy="100" iyz="0" izz="100" />
        </inertial>
        <visual>
            <origin xyz="0 0 0" rpy="0 0 0"/>
            <geometry>
                <box size="0 0 0" />
            </geometry>
            <material name="blue">
                <color rgba="0 0.0 1.0 1.0"/>
            </material>
        </visual>
        <collision>
            <origin xyz="0 0 0" rpy="0 0 0"/>
            <geometry>
                <box size="0 0 0" />
            </geometry>
        </collision>
    </link>
    <joint name="Cube06_Link7" type="revolute">
       <parent link="Cube06"/>
       <child  link="Link7"/>
       <origin rpy="0 0 0" xyz="0 0 0" />
       <axis xyz="0 1 0"/>
       <limit effort="0.0" lower="-3.14159" upper="3.14159" velocity="0.0"/>
    </joint>
    <link name="Link7">
        <inertial>
            <origin xyz="0.0 0.0 -0.11831207363408672" rpy="0 0 0"/>
            <mass value="1" />
            <inertia ixx="100" ixy="0" ixz="0" iyy="100" iyz="0" izz="100" />
        </inertial>
        <visual>
            <origin xyz="0.0 0.0 -0.11831207363408672" rpy="0 0 0"/>
            <geometry>
                <box size="0.3293331065058907 0.28782225350905843 0.23662414726817343" />
            </geometry>
            <material name="green">
                <color rgba="0 1.0 0.0 1.0"/>
            </material>
        </visual>
        <collision>
            <origin xyz="0.0 0.0 -0.11831207363408672" rpy="0 0 0"/>
            <geometry>
                <box size="0.3293331065058907 0.28782225350905843 0.23662414726817343" />
            </geometry>
        </collision>
    </link>
    <joint name="Link2_Cube07" type="revolute">
       <parent link="Link2"/>
       <child  link="Cube07"/>
       <origin rpy="0 0 0" xyz="0.0 -0.34150229863549664 0.3275421778188776" />
       <axis xyz="0 1 0"/>
       <limit effort="0.0" lower="-3.14159" upper="3.14159" velocity="0.0"/>
    </joint>
    <link name="Cube07">
        <inertial>
            <origin xyz="0 0 0" rpy="0 0 0"/>
            <mass value="1" />
            <inertia ixx="100" ixy="0" ixz="0" iyy="100" iyz="0" izz="100" />
        </inertial>
        <visual>
            <origin xyz="0 0 0" rpy="0 0 0"/>
            <geometry>
                <box size="0 0 0" />
            </geometry>
            <material name="blue">
                <color rgba="0 0.0 1.0 1.0"/>
            </material>
        </visual>
        <collision>
            <origin xyz="0 0 0" rpy="0 0 0"/>
            <geometry>
                <box size="0 0 0" />
            </geometry>
        </collision>
    </link>
    <joint name="Cube07_Link8" type="revolute">
       <parent link="Cube07"/>
       <child  link="Link8"/>
       <origin rpy="0 0 0" xyz="0 0 0" />
       <axis xyz="1 0 0"/>
       <limit effort="0.0" lower="-3.14159" upper="3.14159" velocity="0.0"/>
    </joint>
    <link name="Link8">
        <inertial>
            <origin xyz="0.0 -0.23656561486714212 0.0" rpy="0 0 0"/>
            <mass value="1" />
            <inertia ixx="100" ixy="0" ixz="0" iyy="100" iyz="0" izz="100" />
        </inertial>
        <visual>
            <origin xyz="0.0 -0.23656561486714212 0.0" rpy="0 0 0"/>
            <geometry>
                <box size="0.20559105242103826 0.47313122973428423 0.5278408198986158" />
            </geometry>
            <material name="blue">
                <color rgba="0 0.0 1.0 1.0"/>
            </material>
        </visual>
        <collision>
            <origin xyz="0.0 -0.23656561486714212 0.0" rpy="0 0 0"/>
            <geometry>
                <box size="0.20559105242103826 0.47313122973428423 0.5278408198986158" />
            </geometry>
        </collision>
    </link>
</robot>