<robot name = "robot">
    <link name="Link0">
        <inertial>
            <origin xyz="0 0 0.8266870847531728" rpy="0 0 0"/>
            <mass value="1" />
            <inertia ixx="100" ixy="0" ixz="0" iyy="100" iyz="0" izz="100" />
        </inertial>
        <visual>
            <origin xyz="0 0 0.8266870847531728" rpy="0 0 0"/>
            <geometry>
                <box size="0.7464058970825711 0.41298936310775053 0.9064977369248692" />
            </geometry>
            <material name="green">
                <color rgba="0 1.0 0.0 1.0"/>
            </material>
        </visual>
        <collision>
            <origin xyz="0 0 0.8266870847531728" rpy="0 0 0"/>
            <geometry>
                <box size="0.7464058970825711 0.41298936310775053 0.9064977369248692" />
            </geometry>
        </collision>
    </link>
    <joint name="Link0_Link1" type="revolute">
       <parent link="Link0"/>
       <child  link="Link1"/>
       <origin rpy="0 0 0" xyz="0.0 0.0 0.37343821629073815" />
       <axis xyz="1 0 0"/>
       <limit effort="0.0" lower="-3.14159" upper="3.14159" velocity="0.0"/>
    </joint>
    <link name="Link1">
        <inertial>
            <origin xyz="0.0 0.0 -0.1" rpy="0 0 0"/>
            <mass value="1" />
            <inertia ixx="100" ixy="0" ixz="0" iyy="100" iyz="0" izz="100" />
        </inertial>
        <visual>
            <origin xyz="0.0 0.0 -0.1" rpy="0 0 0"/>
            <geometry>
                <box size="0.2 0.27166607599389825 0.2" />
            </geometry>
            <material name="blue">
                <color rgba="0 0.0 1.0 1.0"/>
            </material>
        </visual>
        <collision>
            <origin xyz="0.0 0.0 -0.1" rpy="0 0 0"/>
            <geometry>
                <box size="0.2 0.27166607599389825 0.2" />
            </geometry>
        </collision>
    </link>
    <joint name="Link0_Cube01" type="revolute">
       <parent link="Link0"/>
       <child  link="Cube01"/>
       <origin rpy="0 0 0" xyz="-0.37320294854128555 0.0 0.8266870847531728" />
       <axis xyz="0 1 0"/>
       <limit effort="0.0" lower="-3.14159" upper="3.14159" velocity="0.0"/>
    </joint>
    <link name="Cube01">
        <inertial>
            <origin xyz="0 0 0" rpy="0 0 0"/>
            <mass value="1" />
            <inertia ixx="100" ixy="0" ixz="0" iyy="100" iyz="0" izz="100" />
        </inertial>
        <visual>
            <origin xyz="0 0 0" rpy="0 0 0"/>
            <geometry>
                <box size="0 0 0" />
            </geometry>
            <material name="blue">
                <color rgba="0 0.0 1.0 1.0"/>
            </material>
        </visual>
        <collision>
            <origin xyz="0 0 0" rpy="0 0 0"/>
            <geometry>
                <box size="0 0 0" />
            </geometry>
        </collision>
    </link>
    <joint name="Cube01_Link2" type="revolute">
       <parent link="Cube01"/>
       <child  link="Link2"/>
       <origin rpy="0 0 0" xyz="0 0 0" />
       <axis xyz="1 0 0"/>
       <limit effort="0.0" lower="-3.14159" upper="3.14159" velocity="0.0"/>
    </joint>
    <link name="Link2">
        <inertial>
            <origin xyz="-0.28970029354889126 0.0 0.0" rpy="0 0 0"/>
            <mass value="1" />
            <inertia ixx="100" ixy="0" ixz="0" iyy="100" iyz="0" izz="100" />
        </inertial>
        <visual>
            <origin xyz="-0.28970029354889126 0.0 0.0" rpy="0 0 0"/>
            <geometry>
                <box size="0.5794005870977825 0.3337211385820832 0.2205320334116194" />
            </geometry>
            <material name="blue">
                <color rgba="0 0.0 1.0 1.0"/>
            </material>
        </visual>
        <collision>
            <origin xyz="-0.28970029354889126 0.0 0.0" rpy="0 0 0"/>
            <geometry>
                <box size="0.5794005870977825 0.3337211385820832 0.2205320334116194" />
            </geometry>
        </collision>
    </link>
</robot>