<robot name = "robot">
    <link name="Link0">
        <inertial>
            <origin xyz="0 0 1.167610755355873" rpy="0 0 0"/>
            <mass value="1" />
            <inertia ixx="100" ixy="0" ixz="0" iyy="100" iyz="0" izz="100" />
        </inertial>
        <visual>
            <origin xyz="0 0 1.167610755355873" rpy="0 0 0"/>
            <geometry>
                <box size="0.5343258081684854 0.4135018209343323 0.7389825399633312" />
            </geometry>
            <material name="green">
                <color rgba="0 1.0 0.0 1.0"/>
            </material>
        </visual>
        <collision>
            <origin xyz="0 0 1.167610755355873" rpy="0 0 0"/>
            <geometry>
                <box size="0.5343258081684854 0.4135018209343323 0.7389825399633312" />
            </geometry>
        </collision>
    </link>
    <joint name="Link0_Link1" type="revolute">
       <parent link="Link0"/>
       <child  link="Link1"/>
       <origin rpy="0 0 0" xyz="0.0 0.0 1.5371020253375387" />
       <axis xyz="0 1 0"/>
       <limit effort="0.0" lower="-3.14159" upper="3.14159" velocity="0.0"/>
    </joint>
    <link name="Link1">
        <inertial>
            <origin xyz="0.0 0.0 0.3681088216287377" rpy="0 0 0"/>
            <mass value="1" />
            <inertia ixx="100" ixy="0" ixz="0" iyy="100" iyz="0" izz="100" />
        </inertial>
        <visual>
            <origin xyz="0.0 0.0 0.3681088216287377" rpy="0 0 0"/>
            <geometry>
                <box size="0.5270339711814158 0.28790580550743394 0.7362176432574754" />
            </geometry>
            <material name="green">
                <color rgba="0 1.0 0.0 1.0"/>
            </material>
        </visual>
        <collision>
            <origin xyz="0.0 0.0 0.3681088216287377" rpy="0 0 0"/>
            <geometry>
                <box size="0.5270339711814158 0.28790580550743394 0.7362176432574754" />
            </geometry>
        </collision>
    </link>
    <joint name="Link0_Link2" type="revolute">
       <parent link="Link0"/>
       <child  link="Link2"/>
       <origin rpy="0 0 0" xyz="0.0 0.0 0.7981194853742074" />
       <axis xyz="0 1 0"/>
       <limit effort="0.0" lower="-3.14159" upper="3.14159" velocity="0.0"/>
    </joint>
    <link name="Link2">
        <inertial>
            <origin xyz="0.0 0.0 -0.10160008411562887" rpy="0 0 0"/>
            <mass value="1" />
            <inertia ixx="100" ixy="0" ixz="0" iyy="100" iyz="0" izz="100" />
        </inertial>
        <visual>
            <origin xyz="0.0 0.0 -0.10160008411562887" rpy="0 0 0"/>
            <geometry>
                <box size="0.23885174248790353 0.22797405448250274 0.20320016823125775" />
            </geometry>
            <material name="green">
                <color rgba="0 1.0 0.0 1.0"/>
            </material>
        </visual>
        <collision>
            <origin xyz="0.0 0.0 -0.10160008411562887" rpy="0 0 0"/>
            <geometry>
                <box size="0.23885174248790353 0.22797405448250274 0.20320016823125775" />
            </geometry>
        </collision>
    </link>
</robot>