<robot name = "robot">
    <link name="Link0">
        <inertial>
            <origin xyz="0 0 2.387483917318983" rpy="0 0 0"/>
            <mass value="1" />
            <inertia ixx="100" ixy="0" ixz="0" iyy="100" iyz="0" izz="100" />
        </inertial>
        <visual>
            <origin xyz="0 0 2.387483917318983" rpy="0 0 0"/>
            <geometry>
                <box size="0.6754408188841374 0.7065363057834593 0.918876486368553" />
            </geometry>
            <material name="green">
                <color rgba="0 1.0 0.0 1.0"/>
            </material>
        </visual>
        <collision>
            <origin xyz="0 0 2.387483917318983" rpy="0 0 0"/>
            <geometry>
                <box size="0.6754408188841374 0.7065363057834593 0.918876486368553" />
            </geometry>
        </collision>
    </link>
    <joint name="Link0_Cube00" type="revolute">
       <parent link="Link0"/>
       <child  link="Cube00"/>
       <origin rpy="0 0 0" xyz="0.0 0.0 2.8469221605032597" />
       <axis xyz="0 1 0"/>
       <limit effort="0.0" lower="-3.14159" upper="3.14159" velocity="0.0"/>
    </joint>
    <link name="Cube00">
        <inertial>
            <origin xyz="0 0 0" rpy="0 0 0"/>
            <mass value="1" />
            <inertia ixx="100" ixy="0" ixz="0" iyy="100" iyz="0" izz="100" />
        </inertial>
        <visual>
            <origin xyz="0 0 0" rpy="0 0 0"/>
            <geometry>
                <box size="0 0 0" />
            </geometry>
            <material name="blue">
                <color rgba="0 0.0 1.0 1.0"/>
            </material>
        </visual>
        <collision>
            <origin xyz="0 0 0" rpy="0 0 0"/>
            <geometry>
                <box size="0 0 0" />
            </geometry>
        </collision>
    </link>
    <joint name="Cube00_Link1" type="revolute">
       <parent link="Cube00"/>
       <child  link="Link1"/>
       <origin rpy="0 0 0" xyz="0 0 0" />
       <axis xyz="0 0 1"/>
       <limit effort="0.0" lower="-3.14159" upper="3.14159" velocity="0.0"/>
    </joint>
    <link name="Link1">
        <inertial>
            <origin xyz="0.0 0.0 0.3609426098989431" rpy="0 0 0"/>
            <mass value="1" />
            <inertia ixx="100" ixy="0" ixz="0" iyy="100" iyz="0" izz="100" />
        </inertial>
        <visual>
            <origin xyz="0.0 0.0 0.3609426098989431" rpy="0 0 0"/>
            <geometry>
                <box size="0.7273426436191694 0.5454097217374334 0.7218852197978862" />
            </geometry>
            <material name="blue">
                <color rgba="0 0.0 1.0 1.0"/>
            </material>
        </visual>
        <collision>
            <origin xyz="0.0 0.0 0.3609426098989431" rpy="0 0 0"/>
            <geometry>
                <box size="0.7273426436191694 0.5454097217374334 0.7218852197978862" />
            </geometry>
        </collision>
    </link>
    <joint name="Link1_Link2" type="revolute">
       <parent link="Link1"/>
       <child  link="Link2"/>
       <origin rpy="0 0 0" xyz="0.3636713218095847 0.0 0.3609426098989431" />
       <axis xyz="1 0 0"/>
       <limit effort="0.0" lower="-3.14159" upper="3.14159" velocity="0.0"/>
    </joint>
    <link name="Link2">
        <inertial>
            <origin xyz="0.2448156643580283 0.0 0.0" rpy="0 0 0"/>
            <mass value="1" />
            <inertia ixx="100" ixy="0" ixz="0" iyy="100" iyz="0" izz="100" />
        </inertial>
        <visual>
            <origin xyz="0.2448156643580283 0.0 0.0" rpy="0 0 0"/>
            <geometry>
                <box size="0.4896313287160566 0.4330483138310823 0.2866594115090756" />
            </geometry>
            <material name="green">
                <color rgba="0 1.0 0.0 1.0"/>
            </material>
        </visual>
        <collision>
            <origin xyz="0.2448156643580283 0.0 0.0" rpy="0 0 0"/>
            <geometry>
                <box size="0.4896313287160566 0.4330483138310823 0.2866594115090756" />
            </geometry>
        </collision>
    </link>
    <joint name="Link1_Cube02" type="revolute">
       <parent link="Link1"/>
       <child  link="Cube02"/>
       <origin rpy="0 0 0" xyz="0.0 0.0 0.7218852197978862" />
       <axis xyz="1 0 0"/>
       <limit effort="0.0" lower="-3.14159" upper="3.14159" velocity="0.0"/>
    </joint>
    <link name="Cube02">
        <inertial>
            <origin xyz="0 0 0" rpy="0 0 0"/>
            <mass value="1" />
            <inertia ixx="100" ixy="0" ixz="0" iyy="100" iyz="0" izz="100" />
        </inertial>
        <visual>
            <origin xyz="0 0 0" rpy="0 0 0"/>
            <geometry>
                <box size="0 0 0" />
            </geometry>
            <material name="blue">
                <color rgba="0 0.0 1.0 1.0"/>
            </material>
        </visual>
        <collision>
            <origin xyz="0 0 0" rpy="0 0 0"/>
            <geometry>
                <box size="0 0 0" />
            </geometry>
        </collision>
    </link>
    <joint name="Cube02_Cube12" type="revolute">
       <parent link="Cube02"/>
       <child  link="Cube12"/>
       <origin rpy="0 0 0" xyz="0 0 0" />
       <axis xyz="0 1 0"/>
       <limit effort="0.0" lower="-3.14159" upper="3.14159" velocity="0.0"/>
    </joint>
    <link name="Cube12">
        <inertial>
            <origin xyz="0 0 0" rpy="0 0 0"/>
            <mass value="1" />
            <inertia ixx="100" ixy="0" ixz="0" iyy="100" iyz="0" izz="100" />
        </inertial>
        <visual>
            <origin xyz="0 0 0" rpy="0 0 0"/>
            <geometry>
                <box size="0 0 0" />
            </geometry>
            <material name="blue">
                <color rgba="0 0.0 1.0 1.0"/>
            </material>
        </visual>
        <collision>
            <origin xyz="0 0 0" rpy="0 0 0"/>
            <geometry>
                <box size="0 0 0" />
            </geometry>
        </collision>
    </link>
    <joint name="Cube12_Link3" type="revolute">
       <parent link="Cube12"/>
       <child  link="Link3"/>
       <origin rpy="0 0 0" xyz="0 0 0" />
       <axis xyz="0 0 1"/>
       <limit effort="0.0" lower="-3.14159" upper="3.14159" velocity="0.0"/>
    </joint>
    <link name="Link3">
        <inertial>
            <origin xyz="0.0 0.0 0.2782049942008394" rpy="0 0 0"/>
            <mass value="1" />
            <inertia ixx="100" ixy="0" ixz="0" iyy="100" iyz="0" izz="100" />
        </inertial>
        <visual>
            <origin xyz="0.0 0.0 0.2782049942008394" rpy="0 0 0"/>
            <geometry>
                <box size="0.4247763717502192 0.32385584678496404 0.5564099884016788" />
            </geometry>
            <material name="blue">
                <color rgba="0 0.0 1.0 1.0"/>
            </material>
        </visual>
        <collision>
            <origin xyz="0.0 0.0 0.2782049942008394" rpy="0 0 0"/>
            <geometry>
                <box size="0.4247763717502192 0.32385584678496404 0.5564099884016788" />
            </geometry>
        </collision>
    </link>
    <joint name="Link0_Link4" type="revolute">
       <parent link="Link0"/>
       <child  link="Link4"/>
       <origin rpy="0 0 0" xyz="0.0 0.0 1.9280456741347065" />
       <axis xyz="0 0 1"/>
       <limit effort="0.0" lower="-3.14159" upper="3.14159" velocity="0.0"/>
    </joint>
    <link name="Link4">
        <inertial>
            <origin xyz="0.0 0.0 -0.43160260905163417" rpy="0 0 0"/>
            <mass value="1" />
            <inertia ixx="100" ixy="0" ixz="0" iyy="100" iyz="0" izz="100" />
        </inertial>
        <visual>
            <origin xyz="0.0 0.0 -0.43160260905163417" rpy="0 0 0"/>
            <geometry>
                <box size="0.5974379464961459 0.6348003779776645 0.8632052181032683" />
            </geometry>
            <material name="green">
                <color rgba="0 1.0 0.0 1.0"/>
            </material>
        </visual>
        <collision>
            <origin xyz="0.0 0.0 -0.43160260905163417" rpy="0 0 0"/>
            <geometry>
                <box size="0.5974379464961459 0.6348003779776645 0.8632052181032683" />
            </geometry>
        </collision>
    </link>
    <joint name="Link1_Cube04" type="revolute">
       <parent link="Link1"/>
       <child  link="Cube04"/>
       <origin rpy="0 0 0" xyz="-0.3636713218095847 0.0 0.3609426098989431" />
       <axis xyz="0 1 0"/>
       <limit effort="0.0" lower="-3.14159" upper="3.14159" velocity="0.0"/>
    </joint>
    <link name="Cube04">
        <inertial>
            <origin xyz="0 0 0" rpy="0 0 0"/>
            <mass value="1" />
            <inertia ixx="100" ixy="0" ixz="0" iyy="100" iyz="0" izz="100" />
        </inertial>
        <visual>
            <origin xyz="0 0 0" rpy="0 0 0"/>
            <geometry>
                <box size="0 0 0" />
            </geometry>
            <material name="blue">
                <color rgba="0 0.0 1.0 1.0"/>
            </material>
        </visual>
        <collision>
            <origin xyz="0 0 0" rpy="0 0 0"/>
            <geometry>
                <box size="0 0 0" />
            </geometry>
        </collision>
    </link>
    <joint name="Cube04_Link5" type="revolute">
       <parent link="Cube04"/>
       <child  link="Link5"/>
       <origin rpy="0 0 0" xyz="0 0 0" />
       <axis xyz="1 0 0"/>
       <limit effort="0.0" lower="-3.14159" upper="3.14159" velocity="0.0"/>
    </joint>
    <link name="Link5">
        <inertial>
            <origin xyz="-0.28595628729215783 0.0 0.0" rpy="0 0 0"/>
            <mass value="1" />
            <inertia ixx="100" ixy="0" ixz="0" iyy="100" iyz="0" izz="100" />
        </inertial>
        <visual>
            <origin xyz="-0.28595628729215783 0.0 0.0" rpy="0 0 0"/>
            <geometry>
                <box size="0.5719125745843157 0.3480008473633227 0.41090962989669705" />
            </geometry>
            <material name="green">
                <color rgba="0 1.0 0.0 1.0"/>
            </material>
        </visual>
        <collision>
            <origin xyz="-0.28595628729215783 0.0 0.0" rpy="0 0 0"/>
            <geometry>
                <box size="0.5719125745843157 0.3480008473633227 0.41090962989669705" />
            </geometry>
        </collision>
    </link>
    <joint name="Link4_Cube05" type="revolute">
       <parent link="Link4"/>
       <child  link="Cube05"/>
       <origin rpy="0 0 0" xyz="0.0 0.0 -0.8632052181032683" />
       <axis xyz="0 1 0"/>
       <limit effort="0.0" lower="-3.14159" upper="3.14159" velocity="0.0"/>
    </joint>
    <link name="Cube05">
        <inertial>
            <origin xyz="0 0 0" rpy="0 0 0"/>
            <mass value="1" />
            <inertia ixx="100" ixy="0" ixz="0" iyy="100" iyz="0" izz="100" />
        </inertial>
        <visual>
            <origin xyz="0 0 0" rpy="0 0 0"/>
            <geometry>
                <box size="0 0 0" />
            </geometry>
            <material name="blue">
                <color rgba="0 0.0 1.0 1.0"/>
            </material>
        </visual>
        <collision>
            <origin xyz="0 0 0" rpy="0 0 0"/>
            <geometry>
                <box size="0 0 0" />
            </geometry>
        </collision>
    </link>
    <joint name="Cube05_Cube15" type="revolute">
       <parent link="Cube05"/>
       <child  link="Cube15"/>
       <origin rpy="0 0 0" xyz="0 0 0" />
       <axis xyz="1 0 0"/>
       <limit effort="0.0" lower="-3.14159" upper="3.14159" velocity="0.0"/>
    </joint>
    <link name="Cube15">
        <inertial>
            <origin xyz="0 0 0" rpy="0 0 0"/>
            <mass value="1" />
            <inertia ixx="100" ixy="0" ixz="0" iyy="100" iyz="0" izz="100" />
        </inertial>
        <visual>
            <origin xyz="0 0 0" rpy="0 0 0"/>
            <geometry>
                <box size="0 0 0" />
            </geometry>
            <material name="blue">
                <color rgba="0 0.0 1.0 1.0"/>
            </material>
        </visual>
        <collision>
            <origin xyz="0 0 0" rpy="0 0 0"/>
            <geometry>
                <box size="0 0 0" />
            </geometry>
        </collision>
    </link>
    <joint name="Cube15_Link6" type="revolute">
       <parent link="Cube15"/>
       <child  link="Link6"/>
       <origin rpy="0 0 0" xyz="0 0 0" />
       <axis xyz="0 0 1"/>
       <limit effort="0.0" lower="-3.14159" upper="3.14159" velocity="0.0"/>
    </joint>
    <link name="Link6">
        <inertial>
            <origin xyz="0.0 0.0 -0.3190206853802967" rpy="0 0 0"/>
            <mass value="1" />
            <inertia ixx="100" ixy="0" ixz="0" iyy="100" iyz="0" izz="100" />
        </inertial>
        <visual>
            <origin xyz="0.0 0.0 -0.3190206853802967" rpy="0 0 0"/>
            <geometry>
                <box size="0.3563085001914143 0.3146280229111927 0.6380413707605934" />
            </geometry>
            <material name="green">
                <color rgba="0 1.0 0.0 1.0"/>
            </material>
        </visual>
        <collision>
            <origin xyz="0.0 0.0 -0.3190206853802967" rpy="0 0 0"/>
            <geometry>
                <box size="0.3563085001914143 0.3146280229111927 0.6380413707605934" />
            </geometry>
        </collision>
    </link>
</robot>