<robot name = "robot">
    <link name="Link0">
        <inertial>
            <origin xyz="0 0 0.9237839481428015" rpy="0 0 0"/>
            <mass value="1" />
            <inertia ixx="100" ixy="0" ixz="0" iyy="100" iyz="0" izz="100" />
        </inertial>
        <visual>
            <origin xyz="0 0 0.9237839481428015" rpy="0 0 0"/>
            <geometry>
                <box size="0.8387596048350217 0.9230580921110569 0.7994709951366015" />
            </geometry>
            <material name="blue">
                <color rgba="0 0.0 1.0 1.0"/>
            </material>
        </visual>
        <collision>
            <origin xyz="0 0 0.9237839481428015" rpy="0 0 0"/>
            <geometry>
                <box size="0.8387596048350217 0.9230580921110569 0.7994709951366015" />
            </geometry>
        </collision>
    </link>
    <joint name="Link0_Link1" type="revolute">
       <parent link="Link0"/>
       <child  link="Link1"/>
       <origin rpy="0 0 0" xyz="0.0 -0.46152904605552847 0.9237839481428015" />
       <axis xyz="0 1 0"/>
       <limit effort="0.0" lower="-3.14159" upper="3.14159" velocity="0.0"/>
    </joint>
    <link name="Link1">
        <inertial>
            <origin xyz="0.0 -0.33544578495120003 0.0" rpy="0 0 0"/>
            <mass value="1" />
            <inertia ixx="100" ixy="0" ixz="0" iyy="100" iyz="0" izz="100" />
        </inertial>
        <visual>
            <origin xyz="0.0 -0.33544578495120003 0.0" rpy="0 0 0"/>
            <geometry>
                <box size="0.3173274671063129 0.6708915699024001 0.5044555174321685" />
            </geometry>
            <material name="blue">
                <color rgba="0 0.0 1.0 1.0"/>
            </material>
        </visual>
        <collision>
            <origin xyz="0.0 -0.33544578495120003 0.0" rpy="0 0 0"/>
            <geometry>
                <box size="0.3173274671063129 0.6708915699024001 0.5044555174321685" />
            </geometry>
        </collision>
    </link>
    <joint name="Link1_Link2" type="revolute">
       <parent link="Link1"/>
       <child  link="Link2"/>
       <origin rpy="0 0 0" xyz="0.0 -0.6708915699024001 0.0" />
       <axis xyz="0 1 0"/>
       <limit effort="0.0" lower="-3.14159" upper="3.14159" velocity="0.0"/>
    </joint>
    <link name="Link2">
        <inertial>
            <origin xyz="0.0 -0.13678552734445915 0.0" rpy="0 0 0"/>
            <mass value="1" />
            <inertia ixx="100" ixy="0" ixz="0" iyy="100" iyz="0" izz="100" />
        </inertial>
        <visual>
            <origin xyz="0.0 -0.13678552734445915 0.0" rpy="0 0 0"/>
            <geometry>
                <box size="0.43902577303818174 0.2735710546889183 0.36040747326100836" />
            </geometry>
            <material name="blue">
                <color rgba="0 0.0 1.0 1.0"/>
            </material>
        </visual>
        <collision>
            <origin xyz="0.0 -0.13678552734445915 0.0" rpy="0 0 0"/>
            <geometry>
                <box size="0.43902577303818174 0.2735710546889183 0.36040747326100836" />
            </geometry>
        </collision>
    </link>
</robot>