<robot name = "robot">
    <link name="Link0">
        <inertial>
            <origin xyz="0 0 3.706931707299052" rpy="0 0 0"/>
            <mass value="1" />
            <inertia ixx="100" ixy="0" ixz="0" iyy="100" iyz="0" izz="100" />
        </inertial>
        <visual>
            <origin xyz="0 0 3.706931707299052" rpy="0 0 0"/>
            <geometry>
                <box size="0.8926251870056292 0.6045814434263068 0.30351850063641533" />
            </geometry>
            <material name="blue">
                <color rgba="0 0.0 1.0 1.0"/>
            </material>
        </visual>
        <collision>
            <origin xyz="0 0 3.706931707299052" rpy="0 0 0"/>
            <geometry>
                <box size="0.8926251870056292 0.6045814434263068 0.30351850063641533" />
            </geometry>
        </collision>
    </link>
    <joint name="Link0_Link1" type="revolute">
       <parent link="Link0"/>
       <child  link="Link1"/>
       <origin rpy="0 0 0" xyz="-0.4463125935028146 0.0 3.706931707299052" />
       <axis xyz="0 1 0"/>
       <limit effort="0.0" lower="-3.14159" upper="3.14159" velocity="0.0"/>
    </joint>
    <link name="Link1">
        <inertial>
            <origin xyz="-0.4341017402237367 0.0 0.0" rpy="0 0 0"/>
            <mass value="1" />
            <inertia ixx="100" ixy="0" ixz="0" iyy="100" iyz="0" izz="100" />
        </inertial>
        <visual>
            <origin xyz="-0.4341017402237367 0.0 0.0" rpy="0 0 0"/>
            <geometry>
                <box size="0.8682034804474734 0.42096217990507245 0.6313515340406575" />
            </geometry>
            <material name="green">
                <color rgba="0 1.0 0.0 1.0"/>
            </material>
        </visual>
        <collision>
            <origin xyz="-0.4341017402237367 0.0 0.0" rpy="0 0 0"/>
            <geometry>
                <box size="0.8682034804474734 0.42096217990507245 0.6313515340406575" />
            </geometry>
        </collision>
    </link>
    <joint name="Link1_Cube01" type="revolute">
       <parent link="Link1"/>
       <child  link="Cube01"/>
       <origin rpy="0 0 0" xyz="-0.8682034804474734 0.0 0.0" />
       <axis xyz="1 0 0"/>
       <limit effort="0.0" lower="-3.14159" upper="3.14159" velocity="0.0"/>
    </joint>
    <link name="Cube01">
        <inertial>
            <origin xyz="0 0 0" rpy="0 0 0"/>
            <mass value="1" />
            <inertia ixx="100" ixy="0" ixz="0" iyy="100" iyz="0" izz="100" />
        </inertial>
        <visual>
            <origin xyz="0 0 0" rpy="0 0 0"/>
            <geometry>
                <box size="0 0 0" />
            </geometry>
            <material name="blue">
                <color rgba="0 0.0 1.0 1.0"/>
            </material>
        </visual>
        <collision>
            <origin xyz="0 0 0" rpy="0 0 0"/>
            <geometry>
                <box size="0 0 0" />
            </geometry>
        </collision>
    </link>
    <joint name="Cube01_Link2" type="revolute">
       <parent link="Cube01"/>
       <child  link="Link2"/>
       <origin rpy="0 0 0" xyz="0 0 0" />
       <axis xyz="0 1 0"/>
       <limit effort="0.0" lower="-3.14159" upper="3.14159" velocity="0.0"/>
    </joint>
    <link name="Link2">
        <inertial>
            <origin xyz="-0.2899541626760612 0.0 0.0" rpy="0 0 0"/>
            <mass value="1" />
            <inertia ixx="100" ixy="0" ixz="0" iyy="100" iyz="0" izz="100" />
        </inertial>
        <visual>
            <origin xyz="-0.2899541626760612 0.0 0.0" rpy="0 0 0"/>
            <geometry>
                <box size="0.5799083253521224 0.24726712879449916 0.6963651095175805" />
            </geometry>
            <material name="blue">
                <color rgba="0 0.0 1.0 1.0"/>
            </material>
        </visual>
        <collision>
            <origin xyz="-0.2899541626760612 0.0 0.0" rpy="0 0 0"/>
            <geometry>
                <box size="0.5799083253521224 0.24726712879449916 0.6963651095175805" />
            </geometry>
        </collision>
    </link>
    <joint name="Link0_Cube02" type="revolute">
       <parent link="Link0"/>
       <child  link="Cube02"/>
       <origin rpy="0 0 0" xyz="0.4463125935028146 0.0 3.706931707299052" />
       <axis xyz="0 0 1"/>
       <limit effort="0.0" lower="-3.14159" upper="3.14159" velocity="0.0"/>
    </joint>
    <link name="Cube02">
        <inertial>
            <origin xyz="0 0 0" rpy="0 0 0"/>
            <mass value="1" />
            <inertia ixx="100" ixy="0" ixz="0" iyy="100" iyz="0" izz="100" />
        </inertial>
        <visual>
            <origin xyz="0 0 0" rpy="0 0 0"/>
            <geometry>
                <box size="0 0 0" />
            </geometry>
            <material name="blue">
                <color rgba="0 0.0 1.0 1.0"/>
            </material>
        </visual>
        <collision>
            <origin xyz="0 0 0" rpy="0 0 0"/>
            <geometry>
                <box size="0 0 0" />
            </geometry>
        </collision>
    </link>
    <joint name="Cube02_Cube12" type="revolute">
       <parent link="Cube02"/>
       <child  link="Cube12"/>
       <origin rpy="0 0 0" xyz="0 0 0" />
       <axis xyz="0 1 0"/>
       <limit effort="0.0" lower="-3.14159" upper="3.14159" velocity="0.0"/>
    </joint>
    <link name="Cube12">
        <inertial>
            <origin xyz="0 0 0" rpy="0 0 0"/>
            <mass value="1" />
            <inertia ixx="100" ixy="0" ixz="0" iyy="100" iyz="0" izz="100" />
        </inertial>
        <visual>
            <origin xyz="0 0 0" rpy="0 0 0"/>
            <geometry>
                <box size="0 0 0" />
            </geometry>
            <material name="blue">
                <color rgba="0 0.0 1.0 1.0"/>
            </material>
        </visual>
        <collision>
            <origin xyz="0 0 0" rpy="0 0 0"/>
            <geometry>
                <box size="0 0 0" />
            </geometry>
        </collision>
    </link>
    <joint name="Cube12_Link3" type="revolute">
       <parent link="Cube12"/>
       <child  link="Link3"/>
       <origin rpy="0 0 0" xyz="0 0 0" />
       <axis xyz="1 0 0"/>
       <limit effort="0.0" lower="-3.14159" upper="3.14159" velocity="0.0"/>
    </joint>
    <link name="Link3">
        <inertial>
            <origin xyz="0.31545177485449505 0.0 0.0" rpy="0 0 0"/>
            <mass value="1" />
            <inertia ixx="100" ixy="0" ixz="0" iyy="100" iyz="0" izz="100" />
        </inertial>
        <visual>
            <origin xyz="0.31545177485449505 0.0 0.0" rpy="0 0 0"/>
            <geometry>
                <box size="0.6309035497089901 0.6692032395924519 0.4225713096820399" />
            </geometry>
            <material name="blue">
                <color rgba="0 0.0 1.0 1.0"/>
            </material>
        </visual>
        <collision>
            <origin xyz="0.31545177485449505 0.0 0.0" rpy="0 0 0"/>
            <geometry>
                <box size="0.6309035497089901 0.6692032395924519 0.4225713096820399" />
            </geometry>
        </collision>
    </link>
    <joint name="Link0_Link4" type="revolute">
       <parent link="Link0"/>
       <child  link="Link4"/>
       <origin rpy="0 0 0" xyz="0.0 -0.3022907217131534 3.706931707299052" />
       <axis xyz="1 0 0"/>
       <limit effort="0.0" lower="-3.14159" upper="3.14159" velocity="0.0"/>
    </joint>
    <link name="Link4">
        <inertial>
            <origin xyz="0.0 -0.27823942787345246 0.0" rpy="0 0 0"/>
            <mass value="1" />
            <inertia ixx="100" ixy="0" ixz="0" iyy="100" iyz="0" izz="100" />
        </inertial>
        <visual>
            <origin xyz="0.0 -0.27823942787345246 0.0" rpy="0 0 0"/>
            <geometry>
                <box size="0.5558911385554635 0.5564788557469049 0.5265538002458281" />
            </geometry>
            <material name="blue">
                <color rgba="0 0.0 1.0 1.0"/>
            </material>
        </visual>
        <collision>
            <origin xyz="0.0 -0.27823942787345246 0.0" rpy="0 0 0"/>
            <geometry>
                <box size="0.5558911385554635 0.5564788557469049 0.5265538002458281" />
            </geometry>
        </collision>
    </link>
    <joint name="Link2_Cube04" type="revolute">
       <parent link="Link2"/>
       <child  link="Cube04"/>
       <origin rpy="0 0 0" xyz="-0.2899541626760612 0.0 0.34818255475879023" />
       <axis xyz="0 0 1"/>
       <limit effort="0.0" lower="-3.14159" upper="3.14159" velocity="0.0"/>
    </joint>
    <link name="Cube04">
        <inertial>
            <origin xyz="0 0 0" rpy="0 0 0"/>
            <mass value="1" />
            <inertia ixx="100" ixy="0" ixz="0" iyy="100" iyz="0" izz="100" />
        </inertial>
        <visual>
            <origin xyz="0 0 0" rpy="0 0 0"/>
            <geometry>
                <box size="0 0 0" />
            </geometry>
            <material name="blue">
                <color rgba="0 0.0 1.0 1.0"/>
            </material>
        </visual>
        <collision>
            <origin xyz="0 0 0" rpy="0 0 0"/>
            <geometry>
                <box size="0 0 0" />
            </geometry>
        </collision>
    </link>
    <joint name="Cube04_Link5" type="revolute">
       <parent link="Cube04"/>
       <child  link="Link5"/>
       <origin rpy="0 0 0" xyz="0 0 0" />
       <axis xyz="1 0 0"/>
       <limit effort="0.0" lower="-3.14159" upper="3.14159" velocity="0.0"/>
    </joint>
    <link name="Link5">
        <inertial>
            <origin xyz="0.0 0.0 0.2796104084725838" rpy="0 0 0"/>
            <mass value="1" />
            <inertia ixx="100" ixy="0" ixz="0" iyy="100" iyz="0" izz="100" />
        </inertial>
        <visual>
            <origin xyz="0.0 0.0 0.2796104084725838" rpy="0 0 0"/>
            <geometry>
                <box size="0.32737048871508656 0.5396444478912079 0.5592208169451676" />
            </geometry>
            <material name="blue">
                <color rgba="0 0.0 1.0 1.0"/>
            </material>
        </visual>
        <collision>
            <origin xyz="0.0 0.0 0.2796104084725838" rpy="0 0 0"/>
            <geometry>
                <box size="0.32737048871508656 0.5396444478912079 0.5592208169451676" />
            </geometry>
        </collision>
    </link>
    <joint name="Link3_Cube05" type="revolute">
       <parent link="Link3"/>
       <child  link="Cube05"/>
       <origin rpy="0 0 0" xyz="0.31545177485449505 -0.33460161979622594 0.0" />
       <axis xyz="0 1 0"/>
       <limit effort="0.0" lower="-3.14159" upper="3.14159" velocity="0.0"/>
    </joint>
    <link name="Cube05">
        <inertial>
            <origin xyz="0 0 0" rpy="0 0 0"/>
            <mass value="1" />
            <inertia ixx="100" ixy="0" ixz="0" iyy="100" iyz="0" izz="100" />
        </inertial>
        <visual>
            <origin xyz="0 0 0" rpy="0 0 0"/>
            <geometry>
                <box size="0 0 0" />
            </geometry>
            <material name="blue">
                <color rgba="0 0.0 1.0 1.0"/>
            </material>
        </visual>
        <collision>
            <origin xyz="0 0 0" rpy="0 0 0"/>
            <geometry>
                <box size="0 0 0" />
            </geometry>
        </collision>
    </link>
    <joint name="Cube05_Link6" type="revolute">
       <parent link="Cube05"/>
       <child  link="Link6"/>
       <origin rpy="0 0 0" xyz="0 0 0" />
       <axis xyz="0 0 1"/>
       <limit effort="0.0" lower="-3.14159" upper="3.14159" velocity="0.0"/>
    </joint>
    <link name="Link6">
        <inertial>
            <origin xyz="0.0 -0.3157149786385239 0.0" rpy="0 0 0"/>
            <mass value="1" />
            <inertia ixx="100" ixy="0" ixz="0" iyy="100" iyz="0" izz="100" />
        </inertial>
        <visual>
            <origin xyz="0.0 -0.3157149786385239 0.0" rpy="0 0 0"/>
            <geometry>
                <box size="0.45592537143305434 0.6314299572770478 0.3076814627289275" />
            </geometry>
            <material name="blue">
                <color rgba="0 0.0 1.0 1.0"/>
            </material>
        </visual>
        <collision>
            <origin xyz="0.0 -0.3157149786385239 0.0" rpy="0 0 0"/>
            <geometry>
                <box size="0.45592537143305434 0.6314299572770478 0.3076814627289275" />
            </geometry>
        </collision>
    </link>
    <joint name="Link1_Cube06" type="revolute">
       <parent link="Link1"/>
       <child  link="Cube06"/>
       <origin rpy="0 0 0" xyz="-0.4341017402237367 0.0 -0.31567576702032873" />
       <axis xyz="1 0 0"/>
       <limit effort="0.0" lower="-3.14159" upper="3.14159" velocity="0.0"/>
    </joint>
    <link name="Cube06">
        <inertial>
            <origin xyz="0 0 0" rpy="0 0 0"/>
            <mass value="1" />
            <inertia ixx="100" ixy="0" ixz="0" iyy="100" iyz="0" izz="100" />
        </inertial>
        <visual>
            <origin xyz="0 0 0" rpy="0 0 0"/>
            <geometry>
                <box size="0 0 0" />
            </geometry>
            <material name="blue">
                <color rgba="0 0.0 1.0 1.0"/>
            </material>
        </visual>
        <collision>
            <origin xyz="0 0 0" rpy="0 0 0"/>
            <geometry>
                <box size="0 0 0" />
            </geometry>
        </collision>
    </link>
    <joint name="Cube06_Link7" type="revolute">
       <parent link="Cube06"/>
       <child  link="Link7"/>
       <origin rpy="0 0 0" xyz="0 0 0" />
       <axis xyz="0 0 1"/>
       <limit effort="0.0" lower="-3.14159" upper="3.14159" velocity="0.0"/>
    </joint>
    <link name="Link7">
        <inertial>
            <origin xyz="0.0 0.0 -0.28499860380927466" rpy="0 0 0"/>
            <mass value="1" />
            <inertia ixx="100" ixy="0" ixz="0" iyy="100" iyz="0" izz="100" />
        </inertial>
        <visual>
            <origin xyz="0.0 0.0 -0.28499860380927466" rpy="0 0 0"/>
            <geometry>
                <box size="0.35649082022198375 0.44873311241507363 0.5699972076185493" />
            </geometry>
            <material name="blue">
                <color rgba="0 0.0 1.0 1.0"/>
            </material>
        </visual>
        <collision>
            <origin xyz="0.0 0.0 -0.28499860380927466" rpy="0 0 0"/>
            <geometry>
                <box size="0.35649082022198375 0.44873311241507363 0.5699972076185493" />
            </geometry>
        </collision>
    </link>
    <joint name="Link4_Cube07" type="revolute">
       <parent link="Link4"/>
       <child  link="Cube07"/>
       <origin rpy="0 0 0" xyz="0.0 -0.27823942787345246 -0.26327690012291405" />
       <axis xyz="1 0 0"/>
       <limit effort="0.0" lower="-3.14159" upper="3.14159" velocity="0.0"/>
    </joint>
    <link name="Cube07">
        <inertial>
            <origin xyz="0 0 0" rpy="0 0 0"/>
            <mass value="1" />
            <inertia ixx="100" ixy="0" ixz="0" iyy="100" iyz="0" izz="100" />
        </inertial>
        <visual>
            <origin xyz="0 0 0" rpy="0 0 0"/>
            <geometry>
                <box size="0 0 0" />
            </geometry>
            <material name="blue">
                <color rgba="0 0.0 1.0 1.0"/>
            </material>
        </visual>
        <collision>
            <origin xyz="0 0 0" rpy="0 0 0"/>
            <geometry>
                <box size="0 0 0" />
            </geometry>
        </collision>
    </link>
    <joint name="Cube07_Link8" type="revolute">
       <parent link="Cube07"/>
       <child  link="Link8"/>
       <origin rpy="0 0 0" xyz="0 0 0" />
       <axis xyz="0 0 1"/>
       <limit effort="0.0" lower="-3.14159" upper="3.14159" velocity="0.0"/>
    </joint>
    <link name="Link8">
        <inertial>
            <origin xyz="0.0 0.0 -0.24619211172215866" rpy="0 0 0"/>
            <mass value="1" />
            <inertia ixx="100" ixy="0" ixz="0" iyy="100" iyz="0" izz="100" />
        </inertial>
        <visual>
            <origin xyz="0.0 0.0 -0.24619211172215866" rpy="0 0 0"/>
            <geometry>
                <box size="0.35565394540569306 0.24797472456098194 0.4923842234443173" />
            </geometry>
            <material name="blue">
                <color rgba="0 0.0 1.0 1.0"/>
            </material>
        </visual>
        <collision>
            <origin xyz="0.0 0.0 -0.24619211172215866" rpy="0 0 0"/>
            <geometry>
                <box size="0.35565394540569306 0.24797472456098194 0.4923842234443173" />
            </geometry>
        </collision>
    </link>
    <joint name="Link3_Cube08" type="revolute">
       <parent link="Link3"/>
       <child  link="Cube08"/>
       <origin rpy="0 0 0" xyz="0.31545177485449505 0.33460161979622594 0.0" />
       <axis xyz="0 0 1"/>
       <limit effort="0.0" lower="-3.14159" upper="3.14159" velocity="0.0"/>
    </joint>
    <link name="Cube08">
        <inertial>
            <origin xyz="0 0 0" rpy="0 0 0"/>
            <mass value="1" />
            <inertia ixx="100" ixy="0" ixz="0" iyy="100" iyz="0" izz="100" />
        </inertial>
        <visual>
            <origin xyz="0 0 0" rpy="0 0 0"/>
            <geometry>
                <box size="0 0 0" />
            </geometry>
            <material name="blue">
                <color rgba="0 0.0 1.0 1.0"/>
            </material>
        </visual>
        <collision>
            <origin xyz="0 0 0" rpy="0 0 0"/>
            <geometry>
                <box size="0 0 0" />
            </geometry>
        </collision>
    </link>
    <joint name="Cube08_Link9" type="revolute">
       <parent link="Cube08"/>
       <child  link="Link9"/>
       <origin rpy="0 0 0" xyz="0 0 0" />
       <axis xyz="1 0 0"/>
       <limit effort="0.0" lower="-3.14159" upper="3.14159" velocity="0.0"/>
    </joint>
    <link name="Link9">
        <inertial>
            <origin xyz="0.0 0.31693577895359165 0.0" rpy="0 0 0"/>
            <mass value="1" />
            <inertia ixx="100" ixy="0" ixz="0" iyy="100" iyz="0" izz="100" />
        </inertial>
        <visual>
            <origin xyz="0.0 0.31693577895359165 0.0" rpy="0 0 0"/>
            <geometry>
                <box size="0.6463480598652482 0.6338715579071833 0.23107704287212905" />
            </geometry>
            <material name="blue">
                <color rgba="0 0.0 1.0 1.0"/>
            </material>
        </visual>
        <collision>
            <origin xyz="0.0 0.31693577895359165 0.0" rpy="0 0 0"/>
            <geometry>
                <box size="0.6463480598652482 0.6338715579071833 0.23107704287212905" />
            </geometry>
        </collision>
    </link>
    <joint name="Link5_Cube09" type="revolute">
       <parent link="Link5"/>
       <child  link="Cube09"/>
       <origin rpy="0 0 0" xyz="0.0 0.26982222394560396 0.2796104084725838" />
       <axis xyz="1 0 0"/>
       <limit effort="0.0" lower="-3.14159" upper="3.14159" velocity="0.0"/>
    </joint>
    <link name="Cube09">
        <inertial>
            <origin xyz="0 0 0" rpy="0 0 0"/>
            <mass value="1" />
            <inertia ixx="100" ixy="0" ixz="0" iyy="100" iyz="0" izz="100" />
        </inertial>
        <visual>
            <origin xyz="0 0 0" rpy="0 0 0"/>
            <geometry>
                <box size="0 0 0" />
            </geometry>
            <material name="blue">
                <color rgba="0 0.0 1.0 1.0"/>
            </material>
        </visual>
        <collision>
            <origin xyz="0 0 0" rpy="0 0 0"/>
            <geometry>
                <box size="0 0 0" />
            </geometry>
        </collision>
    </link>
    <joint name="Cube09_Link10" type="revolute">
       <parent link="Cube09"/>
       <child  link="Link10"/>
       <origin rpy="0 0 0" xyz="0 0 0" />
       <axis xyz="0 1 0"/>
       <limit effort="0.0" lower="-3.14159" upper="3.14159" velocity="0.0"/>
    </joint>
    <link name="Link10">
        <inertial>
            <origin xyz="0.0 0.2124490589752194 0.0" rpy="0 0 0"/>
            <mass value="1" />
            <inertia ixx="100" ixy="0" ixz="0" iyy="100" iyz="0" izz="100" />
        </inertial>
        <visual>
            <origin xyz="0.0 0.2124490589752194 0.0" rpy="0 0 0"/>
            <geometry>
                <box size="0.44463402437115684 0.4248981179504388 0.20652203181320444" />
            </geometry>
            <material name="green">
                <color rgba="0 1.0 0.0 1.0"/>
            </material>
        </visual>
        <collision>
            <origin xyz="0.0 0.2124490589752194 0.0" rpy="0 0 0"/>
            <geometry>
                <box size="0.44463402437115684 0.4248981179504388 0.20652203181320444" />
            </geometry>
        </collision>
    </link>
</robot>