<robot name = "robot">
    <link name="Link0">
        <inertial>
            <origin xyz="0 0 3.1018957531863762" rpy="0 0 0"/>
            <mass value="1" />
            <inertia ixx="100" ixy="0" ixz="0" iyy="100" iyz="0" izz="100" />
        </inertial>
        <visual>
            <origin xyz="0 0 3.1018957531863762" rpy="0 0 0"/>
            <geometry>
                <box size="0.5269604360082996 0.20513580254716324 0.45578180049046924" />
            </geometry>
            <material name="green">
                <color rgba="0 1.0 0.0 1.0"/>
            </material>
        </visual>
        <collision>
            <origin xyz="0 0 3.1018957531863762" rpy="0 0 0"/>
            <geometry>
                <box size="0.5269604360082996 0.20513580254716324 0.45578180049046924" />
            </geometry>
        </collision>
    </link>
    <joint name="Link0_Cube00" type="revolute">
       <parent link="Link0"/>
       <child  link="Cube00"/>
       <origin rpy="0 0 0" xyz="-0.2634802180041498 0.0 3.1018957531863762" />
       <axis xyz="0 0 1"/>
       <limit effort="0.0" lower="-3.14159" upper="3.14159" velocity="0.0"/>
    </joint>
    <link name="Cube00">
        <inertial>
            <origin xyz="0 0 0" rpy="0 0 0"/>
            <mass value="1" />
            <inertia ixx="100" ixy="0" ixz="0" iyy="100" iyz="0" izz="100" />
        </inertial>
        <visual>
            <origin xyz="0 0 0" rpy="0 0 0"/>
            <geometry>
                <box size="0 0 0" />
            </geometry>
            <material name="blue">
                <color rgba="0 0.0 1.0 1.0"/>
            </material>
        </visual>
        <collision>
            <origin xyz="0 0 0" rpy="0 0 0"/>
            <geometry>
                <box size="0 0 0" />
            </geometry>
        </collision>
    </link>
    <joint name="Cube00_Link1" type="revolute">
       <parent link="Cube00"/>
       <child  link="Link1"/>
       <origin rpy="0 0 0" xyz="0 0 0" />
       <axis xyz="1 0 0"/>
       <limit effort="0.0" lower="-3.14159" upper="3.14159" velocity="0.0"/>
    </joint>
    <link name="Link1">
        <inertial>
            <origin xyz="-0.2608192562126855 0.0 0.0" rpy="0 0 0"/>
            <mass value="1" />
            <inertia ixx="100" ixy="0" ixz="0" iyy="100" iyz="0" izz="100" />
        </inertial>
        <visual>
            <origin xyz="-0.2608192562126855 0.0 0.0" rpy="0 0 0"/>
            <geometry>
                <box size="0.521638512425371 0.2580693457375522 0.26069871936710864" />
            </geometry>
            <material name="blue">
                <color rgba="0 0.0 1.0 1.0"/>
            </material>
        </visual>
        <collision>
            <origin xyz="-0.2608192562126855 0.0 0.0" rpy="0 0 0"/>
            <geometry>
                <box size="0.521638512425371 0.2580693457375522 0.26069871936710864" />
            </geometry>
        </collision>
    </link>
    <joint name="Link0_Link2" type="revolute">
       <parent link="Link0"/>
       <child  link="Link2"/>
       <origin rpy="0 0 0" xyz="0.0 0.0 3.329786653431611" />
       <axis xyz="0 0 1"/>
       <limit effort="0.0" lower="-3.14159" upper="3.14159" velocity="0.0"/>
    </joint>
    <link name="Link2">
        <inertial>
            <origin xyz="0.0 0.0 0.22536837442241744" rpy="0 0 0"/>
            <mass value="1" />
            <inertia ixx="100" ixy="0" ixz="0" iyy="100" iyz="0" izz="100" />
        </inertial>
        <visual>
            <origin xyz="0.0 0.0 0.22536837442241744" rpy="0 0 0"/>
            <geometry>
                <box size="0.31949130973288176 0.2893508560405009 0.4507367488448349" />
            </geometry>
            <material name="blue">
                <color rgba="0 0.0 1.0 1.0"/>
            </material>
        </visual>
        <collision>
            <origin xyz="0.0 0.0 0.22536837442241744" rpy="0 0 0"/>
            <geometry>
                <box size="0.31949130973288176 0.2893508560405009 0.4507367488448349" />
            </geometry>
        </collision>
    </link>
    <joint name="Link2_Cube02" type="revolute">
       <parent link="Link2"/>
       <child  link="Cube02"/>
       <origin rpy="0 0 0" xyz="0.0 0.0 0.4507367488448349" />
       <axis xyz="0 1 0"/>
       <limit effort="0.0" lower="-3.14159" upper="3.14159" velocity="0.0"/>
    </joint>
    <link name="Cube02">
        <inertial>
            <origin xyz="0 0 0" rpy="0 0 0"/>
            <mass value="1" />
            <inertia ixx="100" ixy="0" ixz="0" iyy="100" iyz="0" izz="100" />
        </inertial>
        <visual>
            <origin xyz="0 0 0" rpy="0 0 0"/>
            <geometry>
                <box size="0 0 0" />
            </geometry>
            <material name="blue">
                <color rgba="0 0.0 1.0 1.0"/>
            </material>
        </visual>
        <collision>
            <origin xyz="0 0 0" rpy="0 0 0"/>
            <geometry>
                <box size="0 0 0" />
            </geometry>
        </collision>
    </link>
    <joint name="Cube02_Cube12" type="revolute">
       <parent link="Cube02"/>
       <child  link="Cube12"/>
       <origin rpy="0 0 0" xyz="0 0 0" />
       <axis xyz="1 0 0"/>
       <limit effort="0.0" lower="-3.14159" upper="3.14159" velocity="0.0"/>
    </joint>
    <link name="Cube12">
        <inertial>
            <origin xyz="0 0 0" rpy="0 0 0"/>
            <mass value="1" />
            <inertia ixx="100" ixy="0" ixz="0" iyy="100" iyz="0" izz="100" />
        </inertial>
        <visual>
            <origin xyz="0 0 0" rpy="0 0 0"/>
            <geometry>
                <box size="0 0 0" />
            </geometry>
            <material name="blue">
                <color rgba="0 0.0 1.0 1.0"/>
            </material>
        </visual>
        <collision>
            <origin xyz="0 0 0" rpy="0 0 0"/>
            <geometry>
                <box size="0 0 0" />
            </geometry>
        </collision>
    </link>
    <joint name="Cube12_Link3" type="revolute">
       <parent link="Cube12"/>
       <child  link="Link3"/>
       <origin rpy="0 0 0" xyz="0 0 0" />
       <axis xyz="0 0 1"/>
       <limit effort="0.0" lower="-3.14159" upper="3.14159" velocity="0.0"/>
    </joint>
    <link name="Link3">
        <inertial>
            <origin xyz="0.0 0.0 0.18492082602743004" rpy="0 0 0"/>
            <mass value="1" />
            <inertia ixx="100" ixy="0" ixz="0" iyy="100" iyz="0" izz="100" />
        </inertial>
        <visual>
            <origin xyz="0.0 0.0 0.18492082602743004" rpy="0 0 0"/>
            <geometry>
                <box size="0.2509978709950613 0.21581053212922774 0.3698416520548601" />
            </geometry>
            <material name="blue">
                <color rgba="0 0.0 1.0 1.0"/>
            </material>
        </visual>
        <collision>
            <origin xyz="0.0 0.0 0.18492082602743004" rpy="0 0 0"/>
            <geometry>
                <box size="0.2509978709950613 0.21581053212922774 0.3698416520548601" />
            </geometry>
        </collision>
    </link>
    <joint name="Link0_Cube03" type="revolute">
       <parent link="Link0"/>
       <child  link="Cube03"/>
       <origin rpy="0 0 0" xyz="0.2634802180041498 0.0 3.1018957531863762" />
       <axis xyz="0 1 0"/>
       <limit effort="0.0" lower="-3.14159" upper="3.14159" velocity="0.0"/>
    </joint>
    <link name="Cube03">
        <inertial>
            <origin xyz="0 0 0" rpy="0 0 0"/>
            <mass value="1" />
            <inertia ixx="100" ixy="0" ixz="0" iyy="100" iyz="0" izz="100" />
        </inertial>
        <visual>
            <origin xyz="0 0 0" rpy="0 0 0"/>
            <geometry>
                <box size="0 0 0" />
            </geometry>
            <material name="blue">
                <color rgba="0 0.0 1.0 1.0"/>
            </material>
        </visual>
        <collision>
            <origin xyz="0 0 0" rpy="0 0 0"/>
            <geometry>
                <box size="0 0 0" />
            </geometry>
        </collision>
    </link>
    <joint name="Cube03_Link4" type="revolute">
       <parent link="Cube03"/>
       <child  link="Link4"/>
       <origin rpy="0 0 0" xyz="0 0 0" />
       <axis xyz="1 0 0"/>
       <limit effort="0.0" lower="-3.14159" upper="3.14159" velocity="0.0"/>
    </joint>
    <link name="Link4">
        <inertial>
            <origin xyz="0.20372788455302207 0.0 0.0" rpy="0 0 0"/>
            <mass value="1" />
            <inertia ixx="100" ixy="0" ixz="0" iyy="100" iyz="0" izz="100" />
        </inertial>
        <visual>
            <origin xyz="0.20372788455302207 0.0 0.0" rpy="0 0 0"/>
            <geometry>
                <box size="0.40745576910604414 0.3971799887348502 0.26924765456474903" />
            </geometry>
            <material name="blue">
                <color rgba="0 0.0 1.0 1.0"/>
            </material>
        </visual>
        <collision>
            <origin xyz="0.20372788455302207 0.0 0.0" rpy="0 0 0"/>
            <geometry>
                <box size="0.40745576910604414 0.3971799887348502 0.26924765456474903" />
            </geometry>
        </collision>
    </link>
    <joint name="Link1_Link5" type="revolute">
       <parent link="Link1"/>
       <child  link="Link5"/>
       <origin rpy="0 0 0" xyz="-0.521638512425371 0.0 0.0" />
       <axis xyz="1 0 0"/>
       <limit effort="0.0" lower="-3.14159" upper="3.14159" velocity="0.0"/>
    </joint>
    <link name="Link5">
        <inertial>
            <origin xyz="-0.13209337837574664 0.0 0.0" rpy="0 0 0"/>
            <mass value="1" />
            <inertia ixx="100" ixy="0" ixz="0" iyy="100" iyz="0" izz="100" />
        </inertial>
        <visual>
            <origin xyz="-0.13209337837574664 0.0 0.0" rpy="0 0 0"/>
            <geometry>
                <box size="0.2641867567514933 0.270487403669946 0.33655172817309814" />
            </geometry>
            <material name="blue">
                <color rgba="0 0.0 1.0 1.0"/>
            </material>
        </visual>
        <collision>
            <origin xyz="-0.13209337837574664 0.0 0.0" rpy="0 0 0"/>
            <geometry>
                <box size="0.2641867567514933 0.270487403669946 0.33655172817309814" />
            </geometry>
        </collision>
    </link>
    <joint name="Link4_Cube05" type="revolute">
       <parent link="Link4"/>
       <child  link="Cube05"/>
       <origin rpy="0 0 0" xyz="0.40745576910604414 0.0 0.0" />
       <axis xyz="0 1 0"/>
       <limit effort="0.0" lower="-3.14159" upper="3.14159" velocity="0.0"/>
    </joint>
    <link name="Cube05">
        <inertial>
            <origin xyz="0 0 0" rpy="0 0 0"/>
            <mass value="1" />
            <inertia ixx="100" ixy="0" ixz="0" iyy="100" iyz="0" izz="100" />
        </inertial>
        <visual>
            <origin xyz="0 0 0" rpy="0 0 0"/>
            <geometry>
                <box size="0 0 0" />
            </geometry>
            <material name="blue">
                <color rgba="0 0.0 1.0 1.0"/>
            </material>
        </visual>
        <collision>
            <origin xyz="0 0 0" rpy="0 0 0"/>
            <geometry>
                <box size="0 0 0" />
            </geometry>
        </collision>
    </link>
    <joint name="Cube05_Cube15" type="revolute">
       <parent link="Cube05"/>
       <child  link="Cube15"/>
       <origin rpy="0 0 0" xyz="0 0 0" />
       <axis xyz="0 0 1"/>
       <limit effort="0.0" lower="-3.14159" upper="3.14159" velocity="0.0"/>
    </joint>
    <link name="Cube15">
        <inertial>
            <origin xyz="0 0 0" rpy="0 0 0"/>
            <mass value="1" />
            <inertia ixx="100" ixy="0" ixz="0" iyy="100" iyz="0" izz="100" />
        </inertial>
        <visual>
            <origin xyz="0 0 0" rpy="0 0 0"/>
            <geometry>
                <box size="0 0 0" />
            </geometry>
            <material name="blue">
                <color rgba="0 0.0 1.0 1.0"/>
            </material>
        </visual>
        <collision>
            <origin xyz="0 0 0" rpy="0 0 0"/>
            <geometry>
                <box size="0 0 0" />
            </geometry>
        </collision>
    </link>
    <joint name="Cube15_Link6" type="revolute">
       <parent link="Cube15"/>
       <child  link="Link6"/>
       <origin rpy="0 0 0" xyz="0 0 0" />
       <axis xyz="1 0 0"/>
       <limit effort="0.0" lower="-3.14159" upper="3.14159" velocity="0.0"/>
    </joint>
    <link name="Link6">
        <inertial>
            <origin xyz="0.17700491591479306 0.0 0.0" rpy="0 0 0"/>
            <mass value="1" />
            <inertia ixx="100" ixy="0" ixz="0" iyy="100" iyz="0" izz="100" />
        </inertial>
        <visual>
            <origin xyz="0.17700491591479306 0.0 0.0" rpy="0 0 0"/>
            <geometry>
                <box size="0.3540098318295861 0.30722490317188084 0.28990141731311153" />
            </geometry>
            <material name="blue">
                <color rgba="0 0.0 1.0 1.0"/>
            </material>
        </visual>
        <collision>
            <origin xyz="0.17700491591479306 0.0 0.0" rpy="0 0 0"/>
            <geometry>
                <box size="0.3540098318295861 0.30722490317188084 0.28990141731311153" />
            </geometry>
        </collision>
    </link>
    <joint name="Link4_Cube06" type="revolute">
       <parent link="Link4"/>
       <child  link="Cube06"/>
       <origin rpy="0 0 0" xyz="0.20372788455302207 0.1985899943674251 0.0" />
       <axis xyz="0 1 0"/>
       <limit effort="0.0" lower="-3.14159" upper="3.14159" velocity="0.0"/>
    </joint>
    <link name="Cube06">
        <inertial>
            <origin xyz="0 0 0" rpy="0 0 0"/>
            <mass value="1" />
            <inertia ixx="100" ixy="0" ixz="0" iyy="100" iyz="0" izz="100" />
        </inertial>
        <visual>
            <origin xyz="0 0 0" rpy="0 0 0"/>
            <geometry>
                <box size="0 0 0" />
            </geometry>
            <material name="blue">
                <color rgba="0 0.0 1.0 1.0"/>
            </material>
        </visual>
        <collision>
            <origin xyz="0 0 0" rpy="0 0 0"/>
            <geometry>
                <box size="0 0 0" />
            </geometry>
        </collision>
    </link>
    <joint name="Cube06_Cube16" type="revolute">
       <parent link="Cube06"/>
       <child  link="Cube16"/>
       <origin rpy="0 0 0" xyz="0 0 0" />
       <axis xyz="0 0 1"/>
       <limit effort="0.0" lower="-3.14159" upper="3.14159" velocity="0.0"/>
    </joint>
    <link name="Cube16">
        <inertial>
            <origin xyz="0 0 0" rpy="0 0 0"/>
            <mass value="1" />
            <inertia ixx="100" ixy="0" ixz="0" iyy="100" iyz="0" izz="100" />
        </inertial>
        <visual>
            <origin xyz="0 0 0" rpy="0 0 0"/>
            <geometry>
                <box size="0 0 0" />
            </geometry>
            <material name="blue">
                <color rgba="0 0.0 1.0 1.0"/>
            </material>
        </visual>
        <collision>
            <origin xyz="0 0 0" rpy="0 0 0"/>
            <geometry>
                <box size="0 0 0" />
            </geometry>
        </collision>
    </link>
    <joint name="Cube16_Link7" type="revolute">
       <parent link="Cube16"/>
       <child  link="Link7"/>
       <origin rpy="0 0 0" xyz="0 0 0" />
       <axis xyz="1 0 0"/>
       <limit effort="0.0" lower="-3.14159" upper="3.14159" velocity="0.0"/>
    </joint>
    <link name="Link7">
        <inertial>
            <origin xyz="0.0 0.17120639484302758 0.0" rpy="0 0 0"/>
            <mass value="1" />
            <inertia ixx="100" ixy="0" ixz="0" iyy="100" iyz="0" izz="100" />
        </inertial>
        <visual>
            <origin xyz="0.0 0.17120639484302758 0.0" rpy="0 0 0"/>
            <geometry>
                <box size="0.3066299279297952 0.34241278968605515 0.359595422518035" />
            </geometry>
            <material name="blue">
                <color rgba="0 0.0 1.0 1.0"/>
            </material>
        </visual>
        <collision>
            <origin xyz="0.0 0.17120639484302758 0.0" rpy="0 0 0"/>
            <geometry>
                <box size="0.3066299279297952 0.34241278968605515 0.359595422518035" />
            </geometry>
        </collision>
    </link>
    <joint name="Link7_Cube07" type="revolute">
       <parent link="Link7"/>
       <child  link="Cube07"/>
       <origin rpy="0 0 0" xyz="0.0 0.17120639484302758 0.1797977112590175" />
       <axis xyz="0 1 0"/>
       <limit effort="0.0" lower="-3.14159" upper="3.14159" velocity="0.0"/>
    </joint>
    <link name="Cube07">
        <inertial>
            <origin xyz="0 0 0" rpy="0 0 0"/>
            <mass value="1" />
            <inertia ixx="100" ixy="0" ixz="0" iyy="100" iyz="0" izz="100" />
        </inertial>
        <visual>
            <origin xyz="0 0 0" rpy="0 0 0"/>
            <geometry>
                <box size="0 0 0" />
            </geometry>
            <material name="blue">
                <color rgba="0 0.0 1.0 1.0"/>
            </material>
        </visual>
        <collision>
            <origin xyz="0 0 0" rpy="0 0 0"/>
            <geometry>
                <box size="0 0 0" />
            </geometry>
        </collision>
    </link>
    <joint name="Cube07_Cube17" type="revolute">
       <parent link="Cube07"/>
       <child  link="Cube17"/>
       <origin rpy="0 0 0" xyz="0 0 0" />
       <axis xyz="1 0 0"/>
       <limit effort="0.0" lower="-3.14159" upper="3.14159" velocity="0.0"/>
    </joint>
    <link name="Cube17">
        <inertial>
            <origin xyz="0 0 0" rpy="0 0 0"/>
            <mass value="1" />
            <inertia ixx="100" ixy="0" ixz="0" iyy="100" iyz="0" izz="100" />
        </inertial>
        <visual>
            <origin xyz="0 0 0" rpy="0 0 0"/>
            <geometry>
                <box size="0 0 0" />
            </geometry>
            <material name="blue">
                <color rgba="0 0.0 1.0 1.0"/>
            </material>
        </visual>
        <collision>
            <origin xyz="0 0 0" rpy="0 0 0"/>
            <geometry>
                <box size="0 0 0" />
            </geometry>
        </collision>
    </link>
    <joint name="Cube17_Link8" type="revolute">
       <parent link="Cube17"/>
       <child  link="Link8"/>
       <origin rpy="0 0 0" xyz="0 0 0" />
       <axis xyz="0 0 1"/>
       <limit effort="0.0" lower="-3.14159" upper="3.14159" velocity="0.0"/>
    </joint>
    <link name="Link8">
        <inertial>
            <origin xyz="0.0 0.0 0.1688304444057278" rpy="0 0 0"/>
            <mass value="1" />
            <inertia ixx="100" ixy="0" ixz="0" iyy="100" iyz="0" izz="100" />
        </inertial>
        <visual>
            <origin xyz="0.0 0.0 0.1688304444057278" rpy="0 0 0"/>
            <geometry>
                <box size="0.31553333406454054 0.2524346968821669 0.3376608888114556" />
            </geometry>
            <material name="blue">
                <color rgba="0 0.0 1.0 1.0"/>
            </material>
        </visual>
        <collision>
            <origin xyz="0.0 0.0 0.1688304444057278" rpy="0 0 0"/>
            <geometry>
                <box size="0.31553333406454054 0.2524346968821669 0.3376608888114556" />
            </geometry>
        </collision>
    </link>
</robot>