<robot name = "robot">
    <link name="Link0">
        <inertial>
            <origin xyz="0 0 0.7711869227787735" rpy="0 0 0"/>
            <mass value="1" />
            <inertia ixx="100" ixy="0" ixz="0" iyy="100" iyz="0" izz="100" />
        </inertial>
        <visual>
            <origin xyz="0 0 0.7711869227787735" rpy="0 0 0"/>
            <geometry>
                <box size="0.757251445202958 0.4413612748004929 0.26126914690775654" />
            </geometry>
            <material name="blue">
                <color rgba="0 0.0 1.0 1.0"/>
            </material>
        </visual>
        <collision>
            <origin xyz="0 0 0.7711869227787735" rpy="0 0 0"/>
            <geometry>
                <box size="0.757251445202958 0.4413612748004929 0.26126914690775654" />
            </geometry>
        </collision>
    </link>
    <joint name="Link0_Link1" type="revolute">
       <parent link="Link0"/>
       <child  link="Link1"/>
       <origin rpy="0 0 0" xyz="0.378625722601479 0.0 0.7711869227787735" />
       <axis xyz="0 0 1"/>
       <limit effort="0.0" lower="-3.14159" upper="3.14159" velocity="0.0"/>
    </joint>
    <link name="Link1">
        <inertial>
            <origin xyz="0.2485916045996136 0.0 0.0" rpy="0 0 0"/>
            <mass value="1" />
            <inertia ixx="100" ixy="0" ixz="0" iyy="100" iyz="0" izz="100" />
        </inertial>
        <visual>
            <origin xyz="0.2485916045996136 0.0 0.0" rpy="0 0 0"/>
            <geometry>
                <box size="0.4971832091992272 0.48356903331376944 0.5424242165156192" />
            </geometry>
            <material name="green">
                <color rgba="0 1.0 0.0 1.0"/>
            </material>
        </visual>
        <collision>
            <origin xyz="0.2485916045996136 0.0 0.0" rpy="0 0 0"/>
            <geometry>
                <box size="0.4971832091992272 0.48356903331376944 0.5424242165156192" />
            </geometry>
        </collision>
    </link>
    <joint name="Link1_Link2" type="revolute">
       <parent link="Link1"/>
       <child  link="Link2"/>
       <origin rpy="0 0 0" xyz="0.2485916045996136 0.0 -0.2712121082578096" />
       <axis xyz="0 0 1"/>
       <limit effort="0.0" lower="-3.14159" upper="3.14159" velocity="0.0"/>
    </joint>
    <link name="Link2">
        <inertial>
            <origin xyz="0.0 0.0 -0.16261116712084492" rpy="0 0 0"/>
            <mass value="1" />
            <inertia ixx="100" ixy="0" ixz="0" iyy="100" iyz="0" izz="100" />
        </inertial>
        <visual>
            <origin xyz="0.0 0.0 -0.16261116712084492" rpy="0 0 0"/>
            <geometry>
                <box size="0.4034428731908281 0.24111907045661712 0.32522233424168984" />
            </geometry>
            <material name="blue">
                <color rgba="0 0.0 1.0 1.0"/>
            </material>
        </visual>
        <collision>
            <origin xyz="0.0 0.0 -0.16261116712084492" rpy="0 0 0"/>
            <geometry>
                <box size="0.4034428731908281 0.24111907045661712 0.32522233424168984" />
            </geometry>
        </collision>
    </link>
    <joint name="Link0_Cube02" type="revolute">
       <parent link="Link0"/>
       <child  link="Cube02"/>
       <origin rpy="0 0 0" xyz="-0.378625722601479 0.0 0.7711869227787735" />
       <axis xyz="0 1 0"/>
       <limit effort="0.0" lower="-3.14159" upper="3.14159" velocity="0.0"/>
    </joint>
    <link name="Cube02">
        <inertial>
            <origin xyz="0 0 0" rpy="0 0 0"/>
            <mass value="1" />
            <inertia ixx="100" ixy="0" ixz="0" iyy="100" iyz="0" izz="100" />
        </inertial>
        <visual>
            <origin xyz="0 0 0" rpy="0 0 0"/>
            <geometry>
                <box size="0 0 0" />
            </geometry>
            <material name="blue">
                <color rgba="0 0.0 1.0 1.0"/>
            </material>
        </visual>
        <collision>
            <origin xyz="0 0 0" rpy="0 0 0"/>
            <geometry>
                <box size="0 0 0" />
            </geometry>
        </collision>
    </link>
    <joint name="Cube02_Link3" type="revolute">
       <parent link="Cube02"/>
       <child  link="Link3"/>
       <origin rpy="0 0 0" xyz="0 0 0" />
       <axis xyz="1 0 0"/>
       <limit effort="0.0" lower="-3.14159" upper="3.14159" velocity="0.0"/>
    </joint>
    <link name="Link3">
        <inertial>
            <origin xyz="-0.32209254126472064 0.0 0.0" rpy="0 0 0"/>
            <mass value="1" />
            <inertia ixx="100" ixy="0" ixz="0" iyy="100" iyz="0" izz="100" />
        </inertial>
        <visual>
            <origin xyz="-0.32209254126472064 0.0 0.0" rpy="0 0 0"/>
            <geometry>
                <box size="0.6441850825294413 0.38936868989095735 0.35196339276310873" />
            </geometry>
            <material name="green">
                <color rgba="0 1.0 0.0 1.0"/>
            </material>
        </visual>
        <collision>
            <origin xyz="-0.32209254126472064 0.0 0.0" rpy="0 0 0"/>
            <geometry>
                <box size="0.6441850825294413 0.38936868989095735 0.35196339276310873" />
            </geometry>
        </collision>
    </link>
</robot>