<robot name = "robot">
    <link name="Link0">
        <inertial>
            <origin xyz="0 0 4.5619364471972395" rpy="0 0 0"/>
            <mass value="1" />
            <inertia ixx="100" ixy="0" ixz="0" iyy="100" iyz="0" izz="100" />
        </inertial>
        <visual>
            <origin xyz="0 0 4.5619364471972395" rpy="0 0 0"/>
            <geometry>
                <box size="0.2246066836572867 0.35259260123453573 0.6189195282439335" />
            </geometry>
            <material name="blue">
                <color rgba="0 0.0 1.0 1.0"/>
            </material>
        </visual>
        <collision>
            <origin xyz="0 0 4.5619364471972395" rpy="0 0 0"/>
            <geometry>
                <box size="0.2246066836572867 0.35259260123453573 0.6189195282439335" />
            </geometry>
        </collision>
    </link>
    <joint name="Link0_Cube00" type="revolute">
       <parent link="Link0"/>
       <child  link="Cube00"/>
       <origin rpy="0 0 0" xyz="0.0 0.0 4.2524766830752725" />
       <axis xyz="1 0 0"/>
       <limit effort="0.0" lower="-3.14159" upper="3.14159" velocity="0.0"/>
    </joint>
    <link name="Cube00">
        <inertial>
            <origin xyz="0 0 0" rpy="0 0 0"/>
            <mass value="1" />
            <inertia ixx="100" ixy="0" ixz="0" iyy="100" iyz="0" izz="100" />
        </inertial>
        <visual>
            <origin xyz="0 0 0" rpy="0 0 0"/>
            <geometry>
                <box size="0 0 0" />
            </geometry>
            <material name="blue">
                <color rgba="0 0.0 1.0 1.0"/>
            </material>
        </visual>
        <collision>
            <origin xyz="0 0 0" rpy="0 0 0"/>
            <geometry>
                <box size="0 0 0" />
            </geometry>
        </collision>
    </link>
    <joint name="Cube00_Link1" type="revolute">
       <parent link="Cube00"/>
       <child  link="Link1"/>
       <origin rpy="0 0 0" xyz="0 0 0" />
       <axis xyz="0 1 0"/>
       <limit effort="0.0" lower="-3.14159" upper="3.14159" velocity="0.0"/>
    </joint>
    <link name="Link1">
        <inertial>
            <origin xyz="0.0 0.0 -0.16296737485714846" rpy="0 0 0"/>
            <mass value="1" />
            <inertia ixx="100" ixy="0" ixz="0" iyy="100" iyz="0" izz="100" />
        </inertial>
        <visual>
            <origin xyz="0.0 0.0 -0.16296737485714846" rpy="0 0 0"/>
            <geometry>
                <box size="0.46358917755223933 0.3932113489587059 0.3259347497142969" />
            </geometry>
            <material name="blue">
                <color rgba="0 0.0 1.0 1.0"/>
            </material>
        </visual>
        <collision>
            <origin xyz="0.0 0.0 -0.16296737485714846" rpy="0 0 0"/>
            <geometry>
                <box size="0.46358917755223933 0.3932113489587059 0.3259347497142969" />
            </geometry>
        </collision>
    </link>
    <joint name="Link1_Cube01" type="revolute">
       <parent link="Link1"/>
       <child  link="Cube01"/>
       <origin rpy="0 0 0" xyz="0.0 0.19660567447935295 -0.16296737485714846" />
       <axis xyz="0 0 1"/>
       <limit effort="0.0" lower="-3.14159" upper="3.14159" velocity="0.0"/>
    </joint>
    <link name="Cube01">
        <inertial>
            <origin xyz="0 0 0" rpy="0 0 0"/>
            <mass value="1" />
            <inertia ixx="100" ixy="0" ixz="0" iyy="100" iyz="0" izz="100" />
        </inertial>
        <visual>
            <origin xyz="0 0 0" rpy="0 0 0"/>
            <geometry>
                <box size="0 0 0" />
            </geometry>
            <material name="blue">
                <color rgba="0 0.0 1.0 1.0"/>
            </material>
        </visual>
        <collision>
            <origin xyz="0 0 0" rpy="0 0 0"/>
            <geometry>
                <box size="0 0 0" />
            </geometry>
        </collision>
    </link>
    <joint name="Cube01_Cube11" type="revolute">
       <parent link="Cube01"/>
       <child  link="Cube11"/>
       <origin rpy="0 0 0" xyz="0 0 0" />
       <axis xyz="0 1 0"/>
       <limit effort="0.0" lower="-3.14159" upper="3.14159" velocity="0.0"/>
    </joint>
    <link name="Cube11">
        <inertial>
            <origin xyz="0 0 0" rpy="0 0 0"/>
            <mass value="1" />
            <inertia ixx="100" ixy="0" ixz="0" iyy="100" iyz="0" izz="100" />
        </inertial>
        <visual>
            <origin xyz="0 0 0" rpy="0 0 0"/>
            <geometry>
                <box size="0 0 0" />
            </geometry>
            <material name="blue">
                <color rgba="0 0.0 1.0 1.0"/>
            </material>
        </visual>
        <collision>
            <origin xyz="0 0 0" rpy="0 0 0"/>
            <geometry>
                <box size="0 0 0" />
            </geometry>
        </collision>
    </link>
    <joint name="Cube11_Link2" type="revolute">
       <parent link="Cube11"/>
       <child  link="Link2"/>
       <origin rpy="0 0 0" xyz="0 0 0" />
       <axis xyz="1 0 0"/>
       <limit effort="0.0" lower="-3.14159" upper="3.14159" velocity="0.0"/>
    </joint>
    <link name="Link2">
        <inertial>
            <origin xyz="0.0 0.1521358167169491 0.0" rpy="0 0 0"/>
            <mass value="1" />
            <inertia ixx="100" ixy="0" ixz="0" iyy="100" iyz="0" izz="100" />
        </inertial>
        <visual>
            <origin xyz="0.0 0.1521358167169491 0.0" rpy="0 0 0"/>
            <geometry>
                <box size="0.2501693191641664 0.3042716334338982 0.24828683964249543" />
            </geometry>
            <material name="blue">
                <color rgba="0 0.0 1.0 1.0"/>
            </material>
        </visual>
        <collision>
            <origin xyz="0.0 0.1521358167169491 0.0" rpy="0 0 0"/>
            <geometry>
                <box size="0.2501693191641664 0.3042716334338982 0.24828683964249543" />
            </geometry>
        </collision>
    </link>
    <joint name="Link0_Cube02" type="revolute">
       <parent link="Link0"/>
       <child  link="Cube02"/>
       <origin rpy="0 0 0" xyz="0.0 0.0 4.871396211319206" />
       <axis xyz="0 0 1"/>
       <limit effort="0.0" lower="-3.14159" upper="3.14159" velocity="0.0"/>
    </joint>
    <link name="Cube02">
        <inertial>
            <origin xyz="0 0 0" rpy="0 0 0"/>
            <mass value="1" />
            <inertia ixx="100" ixy="0" ixz="0" iyy="100" iyz="0" izz="100" />
        </inertial>
        <visual>
            <origin xyz="0 0 0" rpy="0 0 0"/>
            <geometry>
                <box size="0 0 0" />
            </geometry>
            <material name="blue">
                <color rgba="0 0.0 1.0 1.0"/>
            </material>
        </visual>
        <collision>
            <origin xyz="0 0 0" rpy="0 0 0"/>
            <geometry>
                <box size="0 0 0" />
            </geometry>
        </collision>
    </link>
    <joint name="Cube02_Link3" type="revolute">
       <parent link="Cube02"/>
       <child  link="Link3"/>
       <origin rpy="0 0 0" xyz="0 0 0" />
       <axis xyz="0 1 0"/>
       <limit effort="0.0" lower="-3.14159" upper="3.14159" velocity="0.0"/>
    </joint>
    <link name="Link3">
        <inertial>
            <origin xyz="0.0 0.0 0.291961489699945" rpy="0 0 0"/>
            <mass value="1" />
            <inertia ixx="100" ixy="0" ixz="0" iyy="100" iyz="0" izz="100" />
        </inertial>
        <visual>
            <origin xyz="0.0 0.0 0.291961489699945" rpy="0 0 0"/>
            <geometry>
                <box size="0.3481044346546945 0.49089583539678794 0.58392297939989" />
            </geometry>
            <material name="green">
                <color rgba="0 1.0 0.0 1.0"/>
            </material>
        </visual>
        <collision>
            <origin xyz="0.0 0.0 0.291961489699945" rpy="0 0 0"/>
            <geometry>
                <box size="0.3481044346546945 0.49089583539678794 0.58392297939989" />
            </geometry>
        </collision>
    </link>
    <joint name="Link1_Cube03" type="revolute">
       <parent link="Link1"/>
       <child  link="Cube03"/>
       <origin rpy="0 0 0" xyz="-0.23179458877611966 0.0 -0.16296737485714846" />
       <axis xyz="0 0 1"/>
       <limit effort="0.0" lower="-3.14159" upper="3.14159" velocity="0.0"/>
    </joint>
    <link name="Cube03">
        <inertial>
            <origin xyz="0 0 0" rpy="0 0 0"/>
            <mass value="1" />
            <inertia ixx="100" ixy="0" ixz="0" iyy="100" iyz="0" izz="100" />
        </inertial>
        <visual>
            <origin xyz="0 0 0" rpy="0 0 0"/>
            <geometry>
                <box size="0 0 0" />
            </geometry>
            <material name="blue">
                <color rgba="0 0.0 1.0 1.0"/>
            </material>
        </visual>
        <collision>
            <origin xyz="0 0 0" rpy="0 0 0"/>
            <geometry>
                <box size="0 0 0" />
            </geometry>
        </collision>
    </link>
    <joint name="Cube03_Link4" type="revolute">
       <parent link="Cube03"/>
       <child  link="Link4"/>
       <origin rpy="0 0 0" xyz="0 0 0" />
       <axis xyz="0 1 0"/>
       <limit effort="0.0" lower="-3.14159" upper="3.14159" velocity="0.0"/>
    </joint>
    <link name="Link4">
        <inertial>
            <origin xyz="-0.16405736862178233 0.0 0.0" rpy="0 0 0"/>
            <mass value="1" />
            <inertia ixx="100" ixy="0" ixz="0" iyy="100" iyz="0" izz="100" />
        </inertial>
        <visual>
            <origin xyz="-0.16405736862178233 0.0 0.0" rpy="0 0 0"/>
            <geometry>
                <box size="0.32811473724356466 0.31729328168737214 0.3577169429072143" />
            </geometry>
            <material name="blue">
                <color rgba="0 0.0 1.0 1.0"/>
            </material>
        </visual>
        <collision>
            <origin xyz="-0.16405736862178233 0.0 0.0" rpy="0 0 0"/>
            <geometry>
                <box size="0.32811473724356466 0.31729328168737214 0.3577169429072143" />
            </geometry>
        </collision>
    </link>
    <joint name="Link3_Cube04" type="revolute">
       <parent link="Link3"/>
       <child  link="Cube04"/>
       <origin rpy="0 0 0" xyz="0.0 0.0 0.58392297939989" />
       <axis xyz="1 0 0"/>
       <limit effort="0.0" lower="-3.14159" upper="3.14159" velocity="0.0"/>
    </joint>
    <link name="Cube04">
        <inertial>
            <origin xyz="0 0 0" rpy="0 0 0"/>
            <mass value="1" />
            <inertia ixx="100" ixy="0" ixz="0" iyy="100" iyz="0" izz="100" />
        </inertial>
        <visual>
            <origin xyz="0 0 0" rpy="0 0 0"/>
            <geometry>
                <box size="0 0 0" />
            </geometry>
            <material name="blue">
                <color rgba="0 0.0 1.0 1.0"/>
            </material>
        </visual>
        <collision>
            <origin xyz="0 0 0" rpy="0 0 0"/>
            <geometry>
                <box size="0 0 0" />
            </geometry>
        </collision>
    </link>
    <joint name="Cube04_Link5" type="revolute">
       <parent link="Cube04"/>
       <child  link="Link5"/>
       <origin rpy="0 0 0" xyz="0 0 0" />
       <axis xyz="0 0 1"/>
       <limit effort="0.0" lower="-3.14159" upper="3.14159" velocity="0.0"/>
    </joint>
    <link name="Link5">
        <inertial>
            <origin xyz="0.0 0.0 0.1855958309545668" rpy="0 0 0"/>
            <mass value="1" />
            <inertia ixx="100" ixy="0" ixz="0" iyy="100" iyz="0" izz="100" />
        </inertial>
        <visual>
            <origin xyz="0.0 0.0 0.1855958309545668" rpy="0 0 0"/>
            <geometry>
                <box size="0.31006448490707994 0.30665077682320485 0.3711916619091336" />
            </geometry>
            <material name="blue">
                <color rgba="0 0.0 1.0 1.0"/>
            </material>
        </visual>
        <collision>
            <origin xyz="0.0 0.0 0.1855958309545668" rpy="0 0 0"/>
            <geometry>
                <box size="0.31006448490707994 0.30665077682320485 0.3711916619091336" />
            </geometry>
        </collision>
    </link>
    <joint name="Link3_Cube05" type="revolute">
       <parent link="Link3"/>
       <child  link="Cube05"/>
       <origin rpy="0 0 0" xyz="0.0 -0.24544791769839397 0.291961489699945" />
       <axis xyz="0 1 0"/>
       <limit effort="0.0" lower="-3.14159" upper="3.14159" velocity="0.0"/>
    </joint>
    <link name="Cube05">
        <inertial>
            <origin xyz="0 0 0" rpy="0 0 0"/>
            <mass value="1" />
            <inertia ixx="100" ixy="0" ixz="0" iyy="100" iyz="0" izz="100" />
        </inertial>
        <visual>
            <origin xyz="0 0 0" rpy="0 0 0"/>
            <geometry>
                <box size="0 0 0" />
            </geometry>
            <material name="blue">
                <color rgba="0 0.0 1.0 1.0"/>
            </material>
        </visual>
        <collision>
            <origin xyz="0 0 0" rpy="0 0 0"/>
            <geometry>
                <box size="0 0 0" />
            </geometry>
        </collision>
    </link>
    <joint name="Cube05_Cube15" type="revolute">
       <parent link="Cube05"/>
       <child  link="Cube15"/>
       <origin rpy="0 0 0" xyz="0 0 0" />
       <axis xyz="1 0 0"/>
       <limit effort="0.0" lower="-3.14159" upper="3.14159" velocity="0.0"/>
    </joint>
    <link name="Cube15">
        <inertial>
            <origin xyz="0 0 0" rpy="0 0 0"/>
            <mass value="1" />
            <inertia ixx="100" ixy="0" ixz="0" iyy="100" iyz="0" izz="100" />
        </inertial>
        <visual>
            <origin xyz="0 0 0" rpy="0 0 0"/>
            <geometry>
                <box size="0 0 0" />
            </geometry>
            <material name="blue">
                <color rgba="0 0.0 1.0 1.0"/>
            </material>
        </visual>
        <collision>
            <origin xyz="0 0 0" rpy="0 0 0"/>
            <geometry>
                <box size="0 0 0" />
            </geometry>
        </collision>
    </link>
    <joint name="Cube15_Link6" type="revolute">
       <parent link="Cube15"/>
       <child  link="Link6"/>
       <origin rpy="0 0 0" xyz="0 0 0" />
       <axis xyz="0 0 1"/>
       <limit effort="0.0" lower="-3.14159" upper="3.14159" velocity="0.0"/>
    </joint>
    <link name="Link6">
        <inertial>
            <origin xyz="0.0 -0.1306541960612233 0.0" rpy="0 0 0"/>
            <mass value="1" />
            <inertia ixx="100" ixy="0" ixz="0" iyy="100" iyz="0" izz="100" />
        </inertial>
        <visual>
            <origin xyz="0.0 -0.1306541960612233 0.0" rpy="0 0 0"/>
            <geometry>
                <box size="0.3607921694626546 0.2613083921224466 0.28432736581621376" />
            </geometry>
            <material name="green">
                <color rgba="0 1.0 0.0 1.0"/>
            </material>
        </visual>
        <collision>
            <origin xyz="0.0 -0.1306541960612233 0.0" rpy="0 0 0"/>
            <geometry>
                <box size="0.3607921694626546 0.2613083921224466 0.28432736581621376" />
            </geometry>
        </collision>
    </link>
    <joint name="Link1_Link7" type="revolute">
       <parent link="Link1"/>
       <child  link="Link7"/>
       <origin rpy="0 0 0" xyz="0.23179458877611966 0.0 -0.16296737485714846" />
       <axis xyz="0 0 1"/>
       <limit effort="0.0" lower="-3.14159" upper="3.14159" velocity="0.0"/>
    </joint>
    <link name="Link7">
        <inertial>
            <origin xyz="0.143581829323305 0.0 0.0" rpy="0 0 0"/>
            <mass value="1" />
            <inertia ixx="100" ixy="0" ixz="0" iyy="100" iyz="0" izz="100" />
        </inertial>
        <visual>
            <origin xyz="0.143581829323305 0.0 0.0" rpy="0 0 0"/>
            <geometry>
                <box size="0.28716365864661 0.20685794953098552 0.3184826520565692" />
            </geometry>
            <material name="blue">
                <color rgba="0 0.0 1.0 1.0"/>
            </material>
        </visual>
        <collision>
            <origin xyz="0.143581829323305 0.0 0.0" rpy="0 0 0"/>
            <geometry>
                <box size="0.28716365864661 0.20685794953098552 0.3184826520565692" />
            </geometry>
        </collision>
    </link>
    <joint name="Link1_Link8" type="revolute">
       <parent link="Link1"/>
       <child  link="Link8"/>
       <origin rpy="0 0 0" xyz="0.0 -0.19660567447935295 -0.16296737485714846" />
       <axis xyz="0 0 1"/>
       <limit effort="0.0" lower="-3.14159" upper="3.14159" velocity="0.0"/>
    </joint>
    <link name="Link8">
        <inertial>
            <origin xyz="0.0 -0.12740174719957512 0.0" rpy="0 0 0"/>
            <mass value="1" />
            <inertia ixx="100" ixy="0" ixz="0" iyy="100" iyz="0" izz="100" />
        </inertial>
        <visual>
            <origin xyz="0.0 -0.12740174719957512 0.0" rpy="0 0 0"/>
            <geometry>
                <box size="0.28086950510170205 0.25480349439915023 0.31536087002436397" />
            </geometry>
            <material name="green">
                <color rgba="0 1.0 0.0 1.0"/>
            </material>
        </visual>
        <collision>
            <origin xyz="0.0 -0.12740174719957512 0.0" rpy="0 0 0"/>
            <geometry>
                <box size="0.28086950510170205 0.25480349439915023 0.31536087002436397" />
            </geometry>
        </collision>
    </link>
    <joint name="Link3_Link9" type="revolute">
       <parent link="Link3"/>
       <child  link="Link9"/>
       <origin rpy="0 0 0" xyz="0.0 0.24544791769839397 0.291961489699945" />
       <axis xyz="0 0 1"/>
       <limit effort="0.0" lower="-3.14159" upper="3.14159" velocity="0.0"/>
    </joint>
    <link name="Link9">
        <inertial>
            <origin xyz="0.0 0.1732308357392606 0.0" rpy="0 0 0"/>
            <mass value="1" />
            <inertia ixx="100" ixy="0" ixz="0" iyy="100" iyz="0" izz="100" />
        </inertial>
        <visual>
            <origin xyz="0.0 0.1732308357392606 0.0" rpy="0 0 0"/>
            <geometry>
                <box size="0.20829339431966398 0.3464616714785212 0.2510418793184192" />
            </geometry>
            <material name="blue">
                <color rgba="0 0.0 1.0 1.0"/>
            </material>
        </visual>
        <collision>
            <origin xyz="0.0 0.1732308357392606 0.0" rpy="0 0 0"/>
            <geometry>
                <box size="0.20829339431966398 0.3464616714785212 0.2510418793184192" />
            </geometry>
        </collision>
    </link>
    <joint name="Link8_Link10" type="revolute">
       <parent link="Link8"/>
       <child  link="Link10"/>
       <origin rpy="0 0 0" xyz="0.0 -0.12740174719957512 -0.15768043501218199" />
       <axis xyz="1 0 0"/>
       <limit effort="0.0" lower="-3.14159" upper="3.14159" velocity="0.0"/>
    </joint>
    <link name="Link10">
        <inertial>
            <origin xyz="0.0 0.0 -0.12642314090778797" rpy="0 0 0"/>
            <mass value="1" />
            <inertia ixx="100" ixy="0" ixz="0" iyy="100" iyz="0" izz="100" />
        </inertial>
        <visual>
            <origin xyz="0.0 0.0 -0.12642314090778797" rpy="0 0 0"/>
            <geometry>
                <box size="0.2565229079769939 0.2821401087111299 0.25284628181557595" />
            </geometry>
            <material name="blue">
                <color rgba="0 0.0 1.0 1.0"/>
            </material>
        </visual>
        <collision>
            <origin xyz="0.0 0.0 -0.12642314090778797" rpy="0 0 0"/>
            <geometry>
                <box size="0.2565229079769939 0.2821401087111299 0.25284628181557595" />
            </geometry>
        </collision>
    </link>
    <joint name="Link8_Cube010" type="revolute">
       <parent link="Link8"/>
       <child  link="Cube010"/>
       <origin rpy="0 0 0" xyz="0.0 -0.12740174719957512 0.15768043501218199" />
       <axis xyz="0 0 1"/>
       <limit effort="0.0" lower="-3.14159" upper="3.14159" velocity="0.0"/>
    </joint>
    <link name="Cube010">
        <inertial>
            <origin xyz="0 0 0" rpy="0 0 0"/>
            <mass value="1" />
            <inertia ixx="100" ixy="0" ixz="0" iyy="100" iyz="0" izz="100" />
        </inertial>
        <visual>
            <origin xyz="0 0 0" rpy="0 0 0"/>
            <geometry>
                <box size="0 0 0" />
            </geometry>
            <material name="blue">
                <color rgba="0 0.0 1.0 1.0"/>
            </material>
        </visual>
        <collision>
            <origin xyz="0 0 0" rpy="0 0 0"/>
            <geometry>
                <box size="0 0 0" />
            </geometry>
        </collision>
    </link>
    <joint name="Cube010_Cube110" type="revolute">
       <parent link="Cube010"/>
       <child  link="Cube110"/>
       <origin rpy="0 0 0" xyz="0 0 0" />
       <axis xyz="0 1 0"/>
       <limit effort="0.0" lower="-3.14159" upper="3.14159" velocity="0.0"/>
    </joint>
    <link name="Cube110">
        <inertial>
            <origin xyz="0 0 0" rpy="0 0 0"/>
            <mass value="1" />
            <inertia ixx="100" ixy="0" ixz="0" iyy="100" iyz="0" izz="100" />
        </inertial>
        <visual>
            <origin xyz="0 0 0" rpy="0 0 0"/>
            <geometry>
                <box size="0 0 0" />
            </geometry>
            <material name="blue">
                <color rgba="0 0.0 1.0 1.0"/>
            </material>
        </visual>
        <collision>
            <origin xyz="0 0 0" rpy="0 0 0"/>
            <geometry>
                <box size="0 0 0" />
            </geometry>
        </collision>
    </link>
    <joint name="Cube110_Link11" type="revolute">
       <parent link="Cube110"/>
       <child  link="Link11"/>
       <origin rpy="0 0 0" xyz="0 0 0" />
       <axis xyz="1 0 0"/>
       <limit effort="0.0" lower="-3.14159" upper="3.14159" velocity="0.0"/>
    </joint>
    <link name="Link11">
        <inertial>
            <origin xyz="0.0 0.0 0.15495577410379716" rpy="0 0 0"/>
            <mass value="1" />
            <inertia ixx="100" ixy="0" ixz="0" iyy="100" iyz="0" izz="100" />
        </inertial>
        <visual>
            <origin xyz="0.0 0.0 0.15495577410379716" rpy="0 0 0"/>
            <geometry>
                <box size="0.30712985572608126 0.2686339050554299 0.3099115482075943" />
            </geometry>
            <material name="green">
                <color rgba="0 1.0 0.0 1.0"/>
            </material>
        </visual>
        <collision>
            <origin xyz="0.0 0.0 0.15495577410379716" rpy="0 0 0"/>
            <geometry>
                <box size="0.30712985572608126 0.2686339050554299 0.3099115482075943" />
            </geometry>
        </collision>
    </link>
    <joint name="Link5_Cube011" type="revolute">
       <parent link="Link5"/>
       <child  link="Cube011"/>
       <origin rpy="0 0 0" xyz="0.15503224245353997 0.0 0.1855958309545668" />
       <axis xyz="1 0 0"/>
       <limit effort="0.0" lower="-3.14159" upper="3.14159" velocity="0.0"/>
    </joint>
    <link name="Cube011">
        <inertial>
            <origin xyz="0 0 0" rpy="0 0 0"/>
            <mass value="1" />
            <inertia ixx="100" ixy="0" ixz="0" iyy="100" iyz="0" izz="100" />
        </inertial>
        <visual>
            <origin xyz="0 0 0" rpy="0 0 0"/>
            <geometry>
                <box size="0 0 0" />
            </geometry>
            <material name="blue">
                <color rgba="0 0.0 1.0 1.0"/>
            </material>
        </visual>
        <collision>
            <origin xyz="0 0 0" rpy="0 0 0"/>
            <geometry>
                <box size="0 0 0" />
            </geometry>
        </collision>
    </link>
    <joint name="Cube011_Cube111" type="revolute">
       <parent link="Cube011"/>
       <child  link="Cube111"/>
       <origin rpy="0 0 0" xyz="0 0 0" />
       <axis xyz="0 1 0"/>
       <limit effort="0.0" lower="-3.14159" upper="3.14159" velocity="0.0"/>
    </joint>
    <link name="Cube111">
        <inertial>
            <origin xyz="0 0 0" rpy="0 0 0"/>
            <mass value="1" />
            <inertia ixx="100" ixy="0" ixz="0" iyy="100" iyz="0" izz="100" />
        </inertial>
        <visual>
            <origin xyz="0 0 0" rpy="0 0 0"/>
            <geometry>
                <box size="0 0 0" />
            </geometry>
            <material name="blue">
                <color rgba="0 0.0 1.0 1.0"/>
            </material>
        </visual>
        <collision>
            <origin xyz="0 0 0" rpy="0 0 0"/>
            <geometry>
                <box size="0 0 0" />
            </geometry>
        </collision>
    </link>
    <joint name="Cube111_Link12" type="revolute">
       <parent link="Cube111"/>
       <child  link="Link12"/>
       <origin rpy="0 0 0" xyz="0 0 0" />
       <axis xyz="0 0 1"/>
       <limit effort="0.0" lower="-3.14159" upper="3.14159" velocity="0.0"/>
    </joint>
    <link name="Link12">
        <inertial>
            <origin xyz="0.14933509199523054 0.0 0.0" rpy="0 0 0"/>
            <mass value="1" />
            <inertia ixx="100" ixy="0" ixz="0" iyy="100" iyz="0" izz="100" />
        </inertial>
        <visual>
            <origin xyz="0.14933509199523054 0.0 0.0" rpy="0 0 0"/>
            <geometry>
                <box size="0.2986701839904611 0.20136114153816626 0.23637577974614735" />
            </geometry>
            <material name="green">
                <color rgba="0 1.0 0.0 1.0"/>
            </material>
        </visual>
        <collision>
            <origin xyz="0.14933509199523054 0.0 0.0" rpy="0 0 0"/>
            <geometry>
                <box size="0.2986701839904611 0.20136114153816626 0.23637577974614735" />
            </geometry>
        </collision>
    </link>
    <joint name="Link4_Link13" type="revolute">
       <parent link="Link4"/>
       <child  link="Link13"/>
       <origin rpy="0 0 0" xyz="-0.16405736862178233 0.0 0.17885847145360714" />
       <axis xyz="0 1 0"/>
       <limit effort="0.0" lower="-3.14159" upper="3.14159" velocity="0.0"/>
    </joint>
    <link name="Link13">
        <inertial>
            <origin xyz="0.0 0.0 0.17430446145953452" rpy="0 0 0"/>
            <mass value="1" />
            <inertia ixx="100" ixy="0" ixz="0" iyy="100" iyz="0" izz="100" />
        </inertial>
        <visual>
            <origin xyz="0.0 0.0 0.17430446145953452" rpy="0 0 0"/>
            <geometry>
                <box size="0.21256628365229124 0.2153006309074871 0.34860892291906903" />
            </geometry>
            <material name="green">
                <color rgba="0 1.0 0.0 1.0"/>
            </material>
        </visual>
        <collision>
            <origin xyz="0.0 0.0 0.17430446145953452" rpy="0 0 0"/>
            <geometry>
                <box size="0.21256628365229124 0.2153006309074871 0.34860892291906903" />
            </geometry>
        </collision>
    </link>
    <joint name="Link5_Cube013" type="revolute">
       <parent link="Link5"/>
       <child  link="Cube013"/>
       <origin rpy="0 0 0" xyz="0.0 0.0 0.3711916619091336" />
       <axis xyz="0 1 0"/>
       <limit effort="0.0" lower="-3.14159" upper="3.14159" velocity="0.0"/>
    </joint>
    <link name="Cube013">
        <inertial>
            <origin xyz="0 0 0" rpy="0 0 0"/>
            <mass value="1" />
            <inertia ixx="100" ixy="0" ixz="0" iyy="100" iyz="0" izz="100" />
        </inertial>
        <visual>
            <origin xyz="0 0 0" rpy="0 0 0"/>
            <geometry>
                <box size="0 0 0" />
            </geometry>
            <material name="blue">
                <color rgba="0 0.0 1.0 1.0"/>
            </material>
        </visual>
        <collision>
            <origin xyz="0 0 0" rpy="0 0 0"/>
            <geometry>
                <box size="0 0 0" />
            </geometry>
        </collision>
    </link>
    <joint name="Cube013_Cube113" type="revolute">
       <parent link="Cube013"/>
       <child  link="Cube113"/>
       <origin rpy="0 0 0" xyz="0 0 0" />
       <axis xyz="0 0 1"/>
       <limit effort="0.0" lower="-3.14159" upper="3.14159" velocity="0.0"/>
    </joint>
    <link name="Cube113">
        <inertial>
            <origin xyz="0 0 0" rpy="0 0 0"/>
            <mass value="1" />
            <inertia ixx="100" ixy="0" ixz="0" iyy="100" iyz="0" izz="100" />
        </inertial>
        <visual>
            <origin xyz="0 0 0" rpy="0 0 0"/>
            <geometry>
                <box size="0 0 0" />
            </geometry>
            <material name="blue">
                <color rgba="0 0.0 1.0 1.0"/>
            </material>
        </visual>
        <collision>
            <origin xyz="0 0 0" rpy="0 0 0"/>
            <geometry>
                <box size="0 0 0" />
            </geometry>
        </collision>
    </link>
    <joint name="Cube113_Link14" type="revolute">
       <parent link="Cube113"/>
       <child  link="Link14"/>
       <origin rpy="0 0 0" xyz="0 0 0" />
       <axis xyz="1 0 0"/>
       <limit effort="0.0" lower="-3.14159" upper="3.14159" velocity="0.0"/>
    </joint>
    <link name="Link14">
        <inertial>
            <origin xyz="0.0 0.0 0.18194171641883186" rpy="0 0 0"/>
            <mass value="1" />
            <inertia ixx="100" ixy="0" ixz="0" iyy="100" iyz="0" izz="100" />
        </inertial>
        <visual>
            <origin xyz="0.0 0.0 0.18194171641883186" rpy="0 0 0"/>
            <geometry>
                <box size="0.30619325742394654 0.22050024841166158 0.3638834328376637" />
            </geometry>
            <material name="blue">
                <color rgba="0 0.0 1.0 1.0"/>
            </material>
        </visual>
        <collision>
            <origin xyz="0.0 0.0 0.18194171641883186" rpy="0 0 0"/>
            <geometry>
                <box size="0.30619325742394654 0.22050024841166158 0.3638834328376637" />
            </geometry>
        </collision>
    </link>
    <joint name="Link9_Cube014" type="revolute">
       <parent link="Link9"/>
       <child  link="Cube014"/>
       <origin rpy="0 0 0" xyz="0.0 0.3464616714785212 0.0" />
       <axis xyz="0 0 1"/>
       <limit effort="0.0" lower="-3.14159" upper="3.14159" velocity="0.0"/>
    </joint>
    <link name="Cube014">
        <inertial>
            <origin xyz="0 0 0" rpy="0 0 0"/>
            <mass value="1" />
            <inertia ixx="100" ixy="0" ixz="0" iyy="100" iyz="0" izz="100" />
        </inertial>
        <visual>
            <origin xyz="0 0 0" rpy="0 0 0"/>
            <geometry>
                <box size="0 0 0" />
            </geometry>
            <material name="blue">
                <color rgba="0 0.0 1.0 1.0"/>
            </material>
        </visual>
        <collision>
            <origin xyz="0 0 0" rpy="0 0 0"/>
            <geometry>
                <box size="0 0 0" />
            </geometry>
        </collision>
    </link>
    <joint name="Cube014_Link15" type="revolute">
       <parent link="Cube014"/>
       <child  link="Link15"/>
       <origin rpy="0 0 0" xyz="0 0 0" />
       <axis xyz="1 0 0"/>
       <limit effort="0.0" lower="-3.14159" upper="3.14159" velocity="0.0"/>
    </joint>
    <link name="Link15">
        <inertial>
            <origin xyz="0.0 0.15821826934279093 0.0" rpy="0 0 0"/>
            <mass value="1" />
            <inertia ixx="100" ixy="0" ixz="0" iyy="100" iyz="0" izz="100" />
        </inertial>
        <visual>
            <origin xyz="0.0 0.15821826934279093 0.0" rpy="0 0 0"/>
            <geometry>
                <box size="0.2795419722136758 0.31643653868558186 0.30167666555991146" />
            </geometry>
            <material name="blue">
                <color rgba="0 0.0 1.0 1.0"/>
            </material>
        </visual>
        <collision>
            <origin xyz="0.0 0.15821826934279093 0.0" rpy="0 0 0"/>
            <geometry>
                <box size="0.2795419722136758 0.31643653868558186 0.30167666555991146" />
            </geometry>
        </collision>
    </link>
</robot>